Workbook

Sheet Caratula
B17: EVALUACIÓN DE UNIFORMIDAD ESPACIAL Y DENSIDAD DE PLANTAS LOGRADAS
B42: Gdor. Irigoyen 283
B44: Trenque Lauquen
B46: TE: 02392-412732

Sheet Lotes App
A1: EMPRESA | B1: Campo | C1: Lote | D1: Cultivo | E1: Antecesor | F1: Espaciamiento (cm) | G1: Semillero | H1: Genética | I1: Calibre | J1: Densidad siembra Recomendada | K1: Observaciones
A2: AGBA | B2: Launania | C2: Lau_8 | D2: Maiz tardio | E2: Soja | I2: - | J2: 6.3
A3: AL | B3: Auca_Loo | C3: AL_10 | D3: Maiz tardio | E3: Pastura
A4: AL | B4: Auca_Loo | C4: AL_11 | D4: Maiz 2da | E4: Cebada
A5: AL | B5: Auca_Loo | C5: AL_12 | D5: Maiz 2da | E5: Cebada
A6: AL | B6: Auca_Loo | C6: AL_2b | D6: Maiz 2da | E6: Triticale Silo
A7: AL | B7: Auca_Loo | C7: AL_3b | D7: Maiz tardio | E7: Pastura
A8: AL | B8: Auca_Loo | C8: AL_4 | D8: Maiz 2da | E8: Cebada
A9: AL | B9: Auca_Loo | C9: AL_5 | D9: Maiz tardio | E9: Pastura
A10: AL | B10: Auca_Loo | C10: AL_6 | D10: Maiz 2da | E10: Cebada
A11: AL | B11: Auca_Loo | C11: AL_7 | D11: Maiz 2da | E11: Triticale Silo
A12: AL | B12: Auca_Loo | C12: AL_8 | D12: Maiz | E12: Soja 2da | F12: 52.5 | G12: Syngenta | H12: nk979 vip3 | J12: 6
A13: AL | B13: Elunen | C13: E_2 | D13: Maiz tardio | E13: Soja
A14: AL | B14: Elunen | C14: E_7 | D14: Maiz | E14: Soja | F14: 52.5 | G14: La Tijereta | H14: lt725 tre | J14: 6.5
A15: AL | B15: Picucho | C15: Pic_1_norte | D15: Maiz tardio | E15: Soja
A16: AL | B16: Picucho | C16: Pic_1_sur | D16: Maiz tardio | E16: Soja
A17: AL | B17: Picucho | C17: Pic_2_norte | D17: Maiz | E17: Soja | F17: 52.5 | G17: Stine | H17: st9939 vip3 | J17: 4.8
A18: AL | B18: Picucho | C18: Pic_2_sur | D18: Maiz | E18: Soja | F18: 52.5 | G18: Stine | H18: st9939 vip3 | J18: 6
A19: AL | B19: Picucho | C19: Pic_3 | D19: Maiz | E19: Soja | F19: 52.5 | G19: Stine | H19: st9939 vip3 | J19: 6
A20: AL | B20: Picucho | C20: Pic_4 | D20: Maiz | E20: Soja | F20: 52.5 | G20: Stine | H20: st9939 vip3 | J20: 6
A21: C4 | B21: Don_Manuel | C21: DM_1-2-3-4 | D21: Maiz tardio | E21: Cultivo de servicio | F21: 52.5 | G21: Brevant | H21: brv8380 pwue | J21: 4
A22: C4 | B22: Don_Manuel | C22: DM_5 | D22: Maiz tardio | E22: Maiz Silo Tardio | F22: 52.5 | G22: Brevant | H22: brv8380 pwue | J22: 4
A23: C4 | B23: Fino | C23: Fino_1 | D23: Maiz tardio | E23: Girasol | F23: 52.5 | H23: brv8380 pwue | J23: 5.5
A24: C4 | B24: Fino | C24: Fino_2 | D24: Maiz tardio | E24: Soja | F24: 52.5 | H24: brv8380 pwue | J24: 5.5
A25: C4 | B25: Fossati | C25: Fossa_1 | D25: Maiz 2da | E25: Cebada Silo | G25: EBC | H25: maria r plus | J25: 4.5
A26: C4 | B26: Fossati | C26: Fossa_2 | D26: Maiz 2da | E26: Cebada Silo | F26: 52.5 | G26: Brevant | H26: brv8380 pwue | J26: 4
A27: C4 | B27: Los_Chañares | C27: LCh_01 | D27: Maiz tardio | E27: Soja | F27: 52.5 | G27: Dekalb | H27: dk6962 tre | J27: 6.8
A28: C4 | B28: Los_Chañares | C28: LCh_13 | D28: Maiz tardio | E28: Soja 2da | F28: 52.5 | G28: Dekalb | H28: dk6962 tre | J28: 6.8
A29: C4 | B29: Los_Chañares | C29: LCh_16 | D29: Maiz tardio | E29: Soja | F29: 52.5 | G29: Dekalb | H29: dk6962 tre | J29: 6.8
A30: C4 | B30: San_Javier | C30: SJa_1 | D30: Maiz | E30: Maiz Silo Tardio | F30: 52.5 | G30: EBC | H30: maria r plus | J30: 4.5
A31: C4 | B31: San_Javier | C31: SJa_3 | D31: Maiz | E31: Maiz Silo 2da | F31: 52.5 | G31: EBC | H31: maria r plus | J31: 4.5
A32: C4 | B32: San_Javier | C32: SJa_4y5 | D32: Maiz | E32: Maiz Silo 2da | F32: 52.5 | G32: EBC | H32: maria r plus | J32: 4.5
A33: C4 | B33: San_José_RGB | C33: SJo_17 | D33: Maiz | E33: Maiz Silo Tardio | F33: 52.5 | G33: EBC | H33: maria r plus | J33: 4.5
A34: C4 | B34: San_José_RGB | C34: SJo_18a | D34: Maiz tardio | E34: Cultivo de Servicio | F34: 52.5 | G34: Brevant | H34: brv8380 pwue | J34: 6
A35: C4 | B35: San_José_RGB | C35: SJo_18b | D35: Maiz tardio | E35: Pastura | F35: 52.5 | G35: Brevant | H35: brv8380 pwue | J35: 6
A36: C4 | B36: San_José_RGB | C36: SJo_6 | D36: Maiz tardio | E36: Cultivo de servicio | F36: 52.5 | G36: Brevant | H36: brv8380 pwue | J36: 4.5
A37: C4 | B37: San_José_RGB | C37: SJo_8 | D37: Maiz 2da | E37: Cebada Silo | F37: 52.5 | G37: Brevant | H37: brv8380 pwue | J37: 5.5
A38: C4 | B38: San_José_RGB | C38: Sjo_8b | D38: Maiz tardio | E38: Cultivo de servicio | F38: 52.5 | G38: Brevant | H38: brv8380 pwue | J38: 6
A39: C4 | B39: Santa_Margarita | C39: SMta_04_n | D39: Maiz tardio | E39: Soja 2da | G39: EBC | H39: maria r plus | J39: 4.5
A40: C4 | B40: Santa_Margarita | C40: SMta_06 | D40: Maiz tardio | E40: Soja | G40: EBC | H40: maria r plus | J40: 4.5
...

Sheet Listado
A1: AMBIENTE REGIONAL | B1: Ambiente | C1: Codigo Amb | E1: Antecesor | F1: Codigo Ant.
A2: L3 (>80% arena) | B2: LOMA 3 | C2: L3 | E2: Arveja | F2: arv
A3: L2 (70-80% arena) | B3: LOMA 2 | C3: L2 | E3: Avena | F3: av
A4: L1 (<70% arena) | B4: LOMA 1 | C4: L1 | E4: Camelina | F4: cam
A5: ML 3 (>80% arena) | B5: MEDIA LOMA 3 | C5: ML3 | E5: Cebada | F5: ce
A6: ML 2 (70-80% arena) | B6: MEDIA LOMA 2 | C6: ML2 | E6: Cebada Silo | F6: ces
A7: ML 1 (<70% arena) | B7: MEDIA LOMA 1 | C7: ML1 | E7: Centeno | F7: cent
A8: ML-T (tapto < 60 cm) | B8: MEDIA LOMA - TAPTO | C8: ML-T | E8: Cultivo de Servicio | F8: cc
A9: B-T1 (tapto <60 cm) | B9: BAJO - TAPTO 1 | C9: B-T1 | E9: Garbanzo | F9: garb
A10: B-T2 (tapto <60 + CaCo3) | B10: BAJO - TAPTO 2 | C10: B-T2 | E10: Girasol | F10: gi
A11: B-T3 (tapto <60 + >8ph) | B11: BAJO - TAPTO 3 | C11: B-T3 | E11: Inundación | F11: inund
A12: B-Ts1 (tosca 60-120cm) | B12: BAJO - TOSCA 1 | C12: B-Ts1 | E12: Maiz | F12: mz
... A20: B3 (> 8ph) | B20: BAJO 3 | C20: B3 | E20: Natural | F20: nat
E21: Papa | F21: papa
E22: Pasto Llorón | F22: LL
E23: Pastura | F23: PP
E24: Soja | F24: sj
E25: Soja 2da | F25: sj2
E26: Sorgo | F26: sg
E27: Sorgo Pastoreo | F27: sgp
E28: Sorgo Silo | F28: sgs
E29: Trigo | F29: tr
E30: Trigo Silo | F30: trs
E31: Verdeo de Invierno | F31: vi
E32: Verdeo de Verano | F32: vv
... E35: Vicia + Graminea silo | F35: grs/vics

Sheet L1
B1: RECUENTOS POR LOTE - MAIZ | AC1: Distanciamiento entre plantas- DATOS DE ORIGEN GRAFICO
B2: Establecimiento: | F2: Fecha: | K2: Estado Fenológico:
AC3: Sector 1 | AG3: Sector 2 | AK3: Sector 3
B4: Potrero: | D4: Dist.med. | E4: Plantas | F4: Desvío | G4: C.V. | H4: Distancias acumuladas entre plantas | AC4: S 1 | AE4: S 2 | AG4: S 1 | AI4: S 2 | AK4: S 1 | AM4: S 2
B5: Sitio: | D5: cm | E5: por ha | F5: plant.cm | J5: 2 | K5: 3 | L5: 4 | M5: 5 | N5: 6 | O5: 7 | P5: 8 | Q5: 9 | R5: 10 | S5: 11 | T5: 12 | U5: 13 | V5: 14 | W5: 15 | X5: 16 | AC5: {=TRANSPOSE(J6:X6)} -> 0 | AD5: 0.25 | AE5: {=TRANSPOSE(J7:X7)} -> 0 | AF5: =+AD5+($D$15/100) -> 0.25 | AG5: {=TRANSPOSE(J8:X8)} -> 0 | AH5: =+AF5+($D$15/100) -> 0.25 | AI5: {=TRANSPOSE(J9:X9)} -> 0 | AJ5: =+AH5+($D$15/100) -> 0.25 | AK5: {=TRANSPOSE(J10:X10)} -> 0 | AL5: =+AJ5+($D$15/100) -> 0.25 | AM5: {=TRANSPOSE(J11:X11)} -> 0 | AN5: =+AL5+($D$15/100) -> 0.25
B6: Densidad de Siembra: | D6: =IF(SUM(J16:X16)=0,0,AVERAGE(J16:X16)) -> 0 | E6: =IF(D6=0,"",100/D6/$D$15*100*10000) | F6: =IF(D6=0,"",STDEV(J16:X16)) | G6: =IF(F6="","",F6/D6) | H6: Sector 1 | I6: Surco 1 | AC6: 0 | AD6: =$AD$5 -> 0.25 | AE6: 0 | AF6: =+AD6+($D$15/100) -> 0.25 | AG6: 0 | AH6: =+AF6+($D$15/100) -> 0.25 | AI6: 0 | AJ6: =+AH6+($D$15/100) -> 0.25 | AK6: 0 | AL6: =+AJ6+($D$15/100) -> 0.25 | AM6: 0 | AN6: =+AL6+($D$15/100) -> 0.25
C7: sem/ha | D7: =IF(SUM(J17:X17)=0,0,AVERAGE(J17:X17)) -> 0 | E7: =IF(D7=0,"",100/D7/$D$15*100*10000) | F7: =IF(D7=0,"",STDEV(J17:X17)) | G7: =IF(F7="","",F7/D7) | I7: Surco 2 | AC7: 0 | AD7: =$AD$5 -> 0.25 | AE7: 0 | AF7: =+AD7+($D$15/100) -> 0.25 | AG7: 0 | AH7: =+AF7+($D$15/100) -> 0.25 | AI7: 0 | AJ7: =+AH7+($D$15/100) -> 0.25 | AK7: 0 | AL7: =+AJ7+($D$15/100) -> 0.25 | AM7: 0 | AN7: =+AL7+($D$15/100) -> 0.25
B8: Antecesor: | D8: =IF(SUM(J18:X18)=0,0,AVERAGE(J18:X18)) -> 0 | E8: =IF(D8=0,"",100/D8/$D$15*100*10000) | F8: =IF(D8=0,"",STDEV(J18:X18)) | G8: =IF(F8="","",F8/D8) | H8: Sector 2 | I8: Surco 1 | AC8: 0 | AD8: =$AD$5 -> 0.25 | AE8: 0 | AF8: =+AD8+($D$15/100) -> 0.25 | AG8: 0 | AH8: =+AF8+($D$15/100) -> 0.25 | AI8: 0 | AJ8: =+AH8+($D$15/100) -> 0.25 | AK8: 0 | AL8: =+AJ8+($D$15/100) -> 0.25 | AM8: 0 | AN8: =+AL8+($D$15/100) -> 0.25
D9: =IF(SUM(J19:X19)=0,0,AVERAGE(J19:X19)) -> 0 | E9: =IF(D9=0,"",100/D9/$D$15*100*10000) | F9: =IF(D9=0,"",STDEV(J19:X19)) | G9: =IF(F9="","",F9/D9) | I9: Surco 2 | AC9: 0 | AD9: =$AD$5 -> 0.25 | AE9: 0 | AF9: =+AD9+($D$15/100) -> 0.25 | AG9: 0 | AH9: =+AF9+($D$15/100) -> 0.25 | AI9: 0 | AJ9: =+AH9+($D$15/100) -> 0.25 | AK9: 0 | AL9: =+AJ9+($D$15/100) -> 0.25 | AM9: 0 | AN9: =+AL9+($D$15/100) -> 0.25
B10: Nombre Contratista: | D10: =IF(SUM(J20:X20)=0,0,AVERAGE(J20:X20)) -> 0 | E10: =IF(D10=0,"",100/D10/$D$15*100*10000) | F10: =IF(D10=0,"",STDEV(J20:X20)) | G10: =IF(F10="","",F10/D10) | H10: Sector 3 | I10: Surco 1 | AC10: 0 | AD10: =$AD$5 -> 0.25 | AE10: 0 | AF10: =+AD10+($D$15/100) -> 0.25 | AG10: 0 | AH10: =+AF10+($D$15/100) -> 0.25 | AI10: 0 | AJ10: =+AH10+($D$15/100) -> 0.25 | AK10: 0 | AL10: =+AJ10+($D$15/100) -> 0.25 | AM10: 0 | AN10: =+AL10+($D$15/100) -> 0.25
D11: =IF(SUM(J21:X21)=0,0,AVERAGE(J21:X21)) -> 0 | E11: =IF(D11=0,"",100/D11/$D$15*100*10000) | F11: =IF(D11=0,"",STDEV(J21:X21)) | G11: =IF(F11="","",F11/D11) | I11: Surco 2 | AC11: 0 | AD11: =$AD$5 -> 0.25 | AE11: 0 | AF11: =+AD11+($D$15/100) -> 0.25 | AG11: 0 | AH11: =+AF11+($D$15/100) -> 0.25 | AI11: 0 | AJ11: =+AH11+($D$15/100) -> 0.25 | AK11: 0 | AL11: =+AJ11+($D$15/100) -> 0.25 | AM11: 0 | AN11: =+AL11+($D$15/100) -> 0.25
B12: Sembradora: | AC12: 0 | AD12: =$AD$5 -> 0.25 | AE12: 0 | AF12: =+AD12+($D$15/100) -> 0.25 | AG12: 0 | AH12: =+AF12+($D$15/100) -> 0.25 | AI12: 0 | AJ12: =+AH12+($D$15/100) -> 0.25 | AK12: 0 | AL12: =+AJ12+($D$15/100) -> 0.25 | AM12: 0 | AN12: =+AL12+($D$15/100) -> 0.25
AC13: 0 | AD13: =$AD$5 -> 0.25 | AE13: 0 | AF13: =+AD13+($D$15/100) -> 0.25 | AG13: 0 | AH13: =+AF13+($D$15/100) -> 0.25 | AI13: 0 | AJ13: =+AH13+($D$15/100) -> 0.25 | AK13: 0 | AL13: =+AJ13+($D$15/100) -> 0.25 | AM13: 0 | AN13: =+AL13+($D$15/100) -> 0.25
D14: =IF(COUNTIF(D6:D13,">0"),SUM(D6:D13)/COUNTIF(D6:D13,">0"),"") | J14: Distancia entre plantas | AC14: 0 | AD14: =$AD$5 -> 0.25 | AE14: 0 | AF14: =+AD14+($D$15/100) -> 0.25 | AG14: 0 | AH14: =+AF14+($D$15/100) -> 0.25 | AI14: 0 | AJ14: =+AH14+($D$15/100) -> 0.25 | AK14: 0 | AL14: =+AJ14+($D$15/100) -> 0.25 | AM14: 0 | AN14: =+AL14+($D$15/100) -> 0.25
B15: Distancia e/surcos (cm) | E15: cm | F15: % Logro | J15: 1-2 | K15: 2-3 | L15: 3-4 | M15: 4-5 | N15: 5-6 | O15: 6-7 | P15: 7-8 | Q15: 8-9 | R15: 9-10 | S15: 10-11 | T15: 11-12 | U15: 12-13 | V15: 13-14 | W15: 14-15 | X15: 15-16 | AC15: 0 | AD15: =$AD$5 -> 0.25 | AE15: 0 | AF15: =+AD15+($D$15/100) -> 0.25 | AG15: 0 | AH15: =+AF15+($D$15/100) -> 0.25 | AI15: 0 | AJ15: =+AH15+($D$15/100) -> 0.25 | AK15: 0 | AL15: =+AJ15+($D$15/100) -> 0.25 | AM15: 0 | AN15: =+AL15+($D$15/100) -> 0.25
B16: Logro promedio de plantas | D16: =IF(SUM(E6:E13)=0,0,AVERAGE(E6:E13)) -> 0 | E16: ptas./ha | F16: =+IF(B7="","",D16/B7*100) | J16: =J6 -> 0 | K16: =K6-J6 -> 0 | L16: =L6-K6 -> 0 | M16: =M6-L6 -> 0 | N16: =N6-M6 -> 0 | O16: =O6-N6 -> 0 | P16: =P6-O6 -> 0 | Q16: =Q6-P6 -> 0 | R16: =R6-Q6 -> 0 | ... X16: =X6-W6 -> 0 | AC16: 0 | AD16: =$AD$5 -> 0.25 | AE16: 0 | AF16: =+AD16+($D$15/100) -> 0.25 | AG16: 0 | AH16: =+AF16+($D$15/100) -> 0.25 | AI16: 0 | AJ16: =+AH16+($D$15/100) -> 0.25 | AK16: 0 | AL16: =+AJ16+($D$15/100) -> 0.25 | AM16: 0 | AN16: =+AL16+($D$15/100) -> 0.25
B17: Desvío uniformidad planteo | D17: =IF(SUM(F6:F13)=0,0,AVERAGE(F6:F13)) -> 0 | E17: cm | J17: =J7 -> 0 | K17: =K7-J7 -> 0 | L17: =L7-K7 -> 0 | M17: =M7-L7 -> 0 | N17: =N7-M7 -> 0 | O17: =O7-N7 -> 0 | P17: =P7-O7 -> 0 | Q17: =Q7-P7 -> 0 | R17: =R7-Q7 -> 0 | ... X17: =X7-W7 -> 0 | AC17: 0 | AD17: =$AD$5 -> 0.25 | AE17: 0 | AF17: =+AD17+($D$15/100) -> 0.25 | AG17: 0 | AH17: =+AF17+($D$15/100) -> 0.25 | AI17: 0 | AJ17: =+AH17+($D$15/100) -> 0.25 | AK17: 0 | AL17: =+AJ17+($D$15/100) -> 0.25 | AM17: 0 | AN17: =+AL17+($D$15/100) -> 0.25
B18: COEFICIENTE DE VARIACIÓN | D18: =IF(SUM(G6:G13)=0,0,AVERAGE(G6:G13)) -> 0 | J18: =J8 -> 0 | K18: =K8-J8 -> 0 | L18: =L8-K8 -> 0 | M18: =M8-L8 -> 0 | N18: =N8-M8 -> 0 | O18: =O8-N8 -> 0 | P18: =P8-O8 -> 0 | Q18: =Q8-P8 -> 0 | R18: =R8-Q8 -> 0 | ... X18: =X8-W8 -> 0
J19: =J9 -> 0 | K19: =K9-J9 -> 0 | L19: =L9-K9 -> 0 | M19: =M9-L9 -> 0 | N19: =N9-M9 -> 0 | O19: =O9-N9 -> 0 | P19: =P9-O9 -> 0 | Q19: =Q9-P9 -> 0 | R19: =R9-Q9 -> 0 | ... X19: =X9-W9 -> 0 | AC19: DISTANCIAMIENTO ENTRE PLANTAS IDEAL-DATOS ORIGEN GRAFICO
B20: Distribución espacial | J20: =J10 -> 0 | K20: =K10-J10 -> 0 | L20: =L10-K10 -> 0 | M20: =M10-L10 -> 0 | N20: =N10-M10 -> 0 | O20: =O10-N10 -> 0 | P20: =P10-O10 -> 0 | Q20: =Q10-P10 -> 0 | R20: =R10-Q10 -> 0 | ... X20: =X10-W10 -> 0 | AC20: =100/(AI23/(100*(100/($D$15/100)))) -> #DIV/0! | AD20: =+$AC$20*J5 -> #DIV/0! | AE20: =+$AC$20*K5 -> #DIV/0! | AF20: =+$AC$20*L5 -> #DIV/0! | AG20: =+$AC$20*M5 -> #DIV/0! | AH20: =+$AC$20*N5 -> #DIV/0! | AI20: =+$AC$20*O5 -> #DIV/0! | AJ20: =+$AC$20*P5 -> #DIV/0! | AK20: =+$AC$20*Q5 -> #DIV/0! | ... AQ20: =+$AC$20*W5 -> #DIV/0!
J21: =J11 -> 0 | K21: =K11-J11 -> 0 | L21: =L11-K11 -> 0 | M21: =M11-L11 -> 0 | N21: =N11-M11 -> 0 | O21: =O11-N11 -> 0 | P21: =P11-O11 -> 0 | Q21: =Q11-P11 -> 0 | R21: =R11-Q11 -> 0 | ... X21: =X11-W11 -> 0 | AC21: =+$AN$5+($D$15/100) -> 0.25 | AD21: =+$AN$5+($D$15/100) -> 0.25 | AE21: =+$AN$5+($D$15/100) -> 0.25 | AF21: =+$AN$5+($D$15/100) -> 0.25 | AG21: =+$AN$5+($D$15/100) -> 0.25 | AH21: =+$AN$5+($D$15/100) -> 0.25 | AI21: =+$AN$5+($D$15/100) -> 0.25 | AJ21: =+$AN$5+($D$15/100) -> 0.25 | ... AQ21: =+$AN$5+($D$15/100) -> 0.25
AC23: PL/HA-DATO ORIGEN GRAFICO= | AI23: =IF(B7="",D16,B7) -> 0
AC26: Densidad de siembra | AH26: =B7 -> 0
AC27: Distancia entre surcos | AH27: =D15/100 -> 0
AC28: Distancia eq 10 m2 (m) | AH28: =IF(AH27="","",10/AH27) -> #DIV/0!
J29: Observaciones: | AC29: Semillas/m lineal | AH29: =IF(AH27="","",1*(AH26/1000)/AH28) -> #DIV/0!
AC30: Distancia e/semillas(cm) | AH30: =IF(AH29="","",1/AH29*100) -> #DIV/0!
AC32: Doble (cm) | AH32: =IF(AH30="","",3) -> #DIV/0!
AC33: Fallo (cm) | AH33: =IF(AH27="","",2*AH30) -> #DIV/0!
AC34: Aceptable

Sheet L2
B1: RECUENTOS POR LOTE - MAIZ | AC1: Distanciamiento entre plantas- DATOS DE ORIGEN GRAFICO
B2: Establecimiento: | F2: Fecha: | K2: Estado Fenológico:
AC3: Sector 1 | AG3: Sector 2 | AK3: Sector 3
B4: Potrero: | D4: Dist.med. | E4: Plantas | F4: Desvío | G4: C.V. | H4: Distancias acumuladas entre plantas | AC4: S 1 | AE4: S 2 | AG4: S 1 | AI4: S 2 | AK4: S 1 | AM4: S 2
B5: Sitio: | D5: cm | E5: por ha | F5: plant.cm | J5: 2 | K5: 3 | L5: 4 | M5: 5 | N5: 6 | O5: 7 | P5: 8 | Q5: 9 | R5: 10 | S5: 11 | T5: 12 | U5: 13 | V5: 14 | W5: 15 | X5: 16 | AC5: {=TRANSPOSE(J6:X6)} -> 0 | AD5: 0.25 | AE5: {=TRANSPOSE(J7:X7)} -> 0 | AF5: =+AD5+($D$15/100) -> 0.25 | AG5: {=TRANSPOSE(J8:X8)} -> 0 | AH5: =+AF5+($D$15/100) -> 0.25 | AI5: {=TRANSPOSE(J9:X9)} -> 0 | AJ5: =+AH5+($D$15/100) -> 0.25 | AK5: {=TRANSPOSE(J10:X10)} -> 0 | AL5: =+AJ5+($D$15/100) -> 0.25 | AM5: {=TRANSPOSE(J11:X11)} -> 0 | AN5: =+AL5+($D$15/100) -> 0.25
B6: Densidad de Siembra: | D6: =IF(SUM(J16:X16)=0,0,AVERAGE(J16:X16)) -> 0 | E6: =IF(D6=0,"",100/D6/$D$15*100*10000) | F6: =IF(D6=0,"",STDEV(J16:X16)) | G6: =IF(F6="","",F6/D6) | H6: Sector 1 | I6: Surco 1 | AC6: 0 | AD6: =$AD$5 -> 0.25 | AE6: 0 | AF6: =+AD6+($D$15/100) -> 0.25 | AG6: 0 | AH6: =+AF6+($D$15/100) -> 0.25 | AI6: 0 | AJ6: =+AH6+($D$15/100) -> 0.25 | AK6: 0 | AL6: =+AJ6+($D$15/100) -> 0.25 | AM6: 0 | AN6: =+AL6+($D$15/100) -> 0.25
C7: sem/ha | D7: =IF(SUM(J17:X17)=0,0,AVERAGE(J17:X17)) -> 0 | E7: =IF(D7=0,"",100/D7/$D$15*100*10000) | F7: =IF(D7=0,"",STDEV(J17:X17)) | G7: =IF(F7="","",F7/D7) | I7: Surco 2 | AC7: 0 | AD7: =$AD$5 -> 0.25 | AE7: 0 | AF7: =+AD7+($D$15/100) -> 0.25 | AG7: 0 | AH7: =+AF7+($D$15/100) -> 0.25 | AI7: 0 | AJ7: =+AH7+($D$15/100) -> 0.25 | AK7: 0 | AL7: =+AJ7+($D$15/100) -> 0.25 | AM7: 0 | AN7: =+AL7+($D$15/100) -> 0.25
B8: Antecesor: | D8: =IF(SUM(J18:X18)=0,0,AVERAGE(J18:X18)) -> 0 | E8: =IF(D8=0,"",100/D8/$D$15*100*10000) | F8: =IF(D8=0,"",STDEV(J18:X18)) | G8: =IF(F8="","",F8/D8) | H8: Sector 2 | I8: Surco 1 | AC8: 0 | AD8: =$AD$5 -> 0.25 | AE8: 0 | AF8: =+AD8+($D$15/100) -> 0.25 | AG8: 0 | AH8: =+AF8+($D$15/100) -> 0.25 | AI8: 0 | AJ8: =+AH8+($D$15/100) -> 0.25 | AK8: 0 | AL8: =+AJ8+($D$15/100) -> 0.25 | AM8: 0 | AN8: =+AL8+($D$15/100) -> 0.25
D9: =IF(SUM(J19:X19)=0,0,AVERAGE(J19:X19)) -> 0 | E9: =IF(D9=0,"",100/D9/$D$15*100*10000) | F9: =IF(D9=0,"",STDEV(J19:X19)) | G9: =IF(F9="","",F9/D9) | I9: Surco 2 | AC9: 0 | AD9: =$AD$5 -> 0.25 | AE9: 0 | AF9: =+AD9+($D$15/100) -> 0.25 | AG9: 0 | AH9: =+AF9+($D$15/100) -> 0.25 | AI9: 0 | AJ9: =+AH9+($D$15/100) -> 0.25 | AK9: 0 | AL9: =+AJ9+($D$15/100) -> 0.25 | AM9: 0 | AN9: =+AL9+($D$15/100) -> 0.25
B10: Nombre Contratista: | D10: =IF(SUM(J20:X20)=0,0,AVERAGE(J20:X20)) -> 0 | E10: =IF(D10=0,"",100/D10/$D$15*100*10000) | F10: =IF(D10=0,"",STDEV(J20:X20)) | G10: =IF(F10="","",F10/D10) | H10: Sector 3 | I10: Surco 1 | AC10: 0 | AD10: =$AD$5 -> 0.25 | AE10: 0 | AF10: =+AD10+($D$15/100) -> 0.25 | AG10: 0 | AH10: =+AF10+($D$15/100) -> 0.25 | AI10: 0 | AJ10: =+AH10+($D$15/100) -> 0.25 | AK10: 0 | AL10: =+AJ10+($D$15/100) -> 0.25 | AM10: 0 | AN10: =+AL10+($D$15/100) -> 0.25
D11: =IF(SUM(J21:X21)=0,0,AVERAGE(J21:X21)) -> 0 | E11: =IF(D11=0,"",100/D11/$D$15*100*10000) | F11: =IF(D11=0,"",STDEV(J21:X21)) | G11: =IF(F11="","",F11/D11) | I11: Surco 2 | AC11: 0 | AD11: =$AD$5 -> 0.25 | AE11: 0 | AF11: =+AD11+($D$15/100) -> 0.25 | AG11: 0 | AH11: =+AF11+($D$15/100) -> 0.25 | AI11: 0 | AJ11: =+AH11+($D$15/100) -> 0.25 | AK11: 0 | AL11: =+AJ11+($D$15/100) -> 0.25 | AM11: 0 | AN11: =+AL11+($D$15/100) -> 0.25
B12: Sembradora: | AC12: 0 | AD12: =$AD$5 -> 0.25 | AE12: 0 | AF12: =+AD12+($D$15/100) -> 0.25 | AG12: 0 | AH12: =+AF12+($D$15/100) -> 0.25 | AI12: 0 | AJ12: =+AH12+($D$15/100) -> 0.25 | AK12: 0 | AL12: =+AJ12+($D$15/100) -> 0.25 | AM12: 0 | AN12: =+AL12+($D$15/100) -> 0.25
AC13: 0 | AD13: =$AD$5 -> 0.25 | AE13: 0 | AF13: =+AD13+($D$15/100) -> 0.25 | AG13: 0 | AH13: =+AF13+($D$15/100) -> 0.25 | AI13: 0 | AJ13: =+AH13+($D$15/100) -> 0.25 | AK13: 0 | AL13: =+AJ13+($D$15/100) -> 0.25 | AM13: 0 | AN13: =+AL13+($D$15/100) -> 0.25
D14: =IF(COUNTIF(D6:D13,">0"),SUM(D6:D13)/COUNTIF(D6:D13,">0"),"") | J14: Distancia entre plantas | AC14: 0 | AD14: =$AD$5 -> 0.25 | AE14: 0 | AF14: =+AD14+($D$15/100) -> 0.25 | AG14: 0 | AH14: =+AF14+($D$15/100) -> 0.25 | AI14: 0 | AJ14: =+AH14+($D$15/100) -> 0.25 | AK14: 0 | AL14: =+AJ14+($D$15/100) -> 0.25 | AM14: 0 | AN14: =+AL14+($D$15/100) -> 0.25
B15: Distancia e/surcos (cm) | E15: cm | F15: % Logro | J15: 1-2 | K15: 2-3 | L15: 3-4 | M15: 4-5 | N15: 5-6 | O15: 6-7 | P15: 7-8 | Q15: 8-9 | R15: 9-10 | S15: 10-11 | T15: 11-12 | U15: 12-13 | V15: 13-14 | W15: 14-15 | X15: 15-16 | AC15: 0 | AD15: =$AD$5 -> 0.25 | AE15: 0 | AF15: =+AD15+($D$15/100) -> 0.25 | AG15: 0 | AH15: =+AF15+($D$15/100) -> 0.25 | AI15: 0 | AJ15: =+AH15+($D$15/100) -> 0.25 | AK15: 0 | AL15: =+AJ15+($D$15/100) -> 0.25 | AM15: 0 | AN15: =+AL15+($D$15/100) -> 0.25
B16: Logro promedio de plantas | D16: =IF(SUM(E6:E13)=0,0,AVERAGE(E6:E13)) -> 0 | E16: ptas./ha | F16: =+IF(B7="","",D16/B7*100) | J16: =J6 -> 0 | K16: =K6-J6 -> 0 | L16: =L6-K6 -> 0 | M16: =M6-L6 -> 0 | N16: =N6-M6 -> 0 | O16: =O6-N6 -> 0 | P16: =P6-O6 -> 0 | Q16: =Q6-P6 -> 0 | R16: =R6-Q6 -> 0 | ... X16: =X6-W6 -> 0 | AC16: 0 | AD16: =$AD$5 -> 0.25 | AE16: 0 | AF16: =+AD16+($D$15/100) -> 0.25 | AG16: 0 | AH16: =+AF16+($D$15/100) -> 0.25 | AI16: 0 | AJ16: =+AH16+($D$15/100) -> 0.25 | AK16: 0 | AL16: =+AJ16+($D$15/100) -> 0.25 | AM16: 0 | AN16: =+AL16+($D$15/100) -> 0.25
B17: Desvío uniformidad planteo | D17: =IF(SUM(F6:F13)=0,0,AVERAGE(F6:F13)) -> 0 | E17: cm | J17: =J7 -> 0 | K17: =K7-J7 -> 0 | L17: =L7-K7 -> 0 | M17: =M7-L7 -> 0 | N17: =N7-M7 -> 0 | O17: =O7-N7 -> 0 | P17: =P7-O7 -> 0 | Q17: =Q7-P7 -> 0 | R17: =R7-Q7 -> 0 | ... X17: =X7-W7 -> 0 | AC17: 0 | AD17: =$AD$5 -> 0.25 | AE17: 0 | AF17: =+AD17+($D$15/100) -> 0.25 | AG17: 0 | AH17: =+AF17+($D$15/100) -> 0.25 | AI17: 0 | AJ17: =+AH17+($D$15/100) -> 0.25 | AK17: 0 | AL17: =+AJ17+($D$15/100) -> 0.25 | AM17: 0 | AN17: =+AL17+($D$15/100) -> 0.25
B18: COEFICIENTE DE VARIACIÓN | D18: =IF(SUM(G6:G13)=0,0,AVERAGE(G6:G13)) -> 0 | J18: =J8 -> 0 | K18: =K8-J8 -> 0 | L18: =L8-K8 -> 0 | M18: =M8-L8 -> 0 | N18: =N8-M8 -> 0 | O18: =O8-N8 -> 0 | P18: =P8-O8 -> 0 | Q18: =Q8-P8 -> 0 | R18: =R8-Q8 -> 0 | ... X18: =X8-W8 -> 0
J19: =J9 -> 0 | K19: =K9-J9 -> 0 | L19: =L9-K9 -> 0 | M19: =M9-L9 -> 0 | N19: =N9-M9 -> 0 | O19: =O9-N9 -> 0 | P19: =P9-O9 -> 0 | Q19: =Q9-P9 -> 0 | R19: =R9-Q9 -> 0 | ... X19: =X9-W9 -> 0 | AC19: DISTANCIAMIENTO ENTRE PLANTAS IDEAL-DATOS ORIGEN GRAFICO
B20: Distribución espacial | J20: =J10 -> 0 | K20: =K10-J10 -> 0 | L20: =L10-K10 -> 0 | M20: =M10-L10 -> 0 | N20: =N10-M10 -> 0 | O20: =O10-N10 -> 0 | P20: =P10-O10 -> 0 | Q20: =Q10-P10 -> 0 | R20: =R10-Q10 -> 0 | ... X20: =X10-W10 -> 0 | AC20: =100/(AI23/(100*(100/($D$15/100)))) -> #DIV/0! | AD20: =+$AC$20*J5 -> #DIV/0! | AE20: =+$AC$20*K5 -> #DIV/0! | AF20: =+$AC$20*L5 -> #DIV/0! | AG20: =+$AC$20*M5 -> #DIV/0! | AH20: =+$AC$20*N5 -> #DIV/0! | AI20: =+$AC$20*O5 -> #DIV/0! | AJ20: =+$AC$20*P5 -> #DIV/0! | AK20: =+$AC$20*Q5 -> #DIV/0! | ... AQ20: =+$AC$20*W5 -> #DIV/0!
J21: =J11 -> 0 | K21: =K11-J11 -> 0 | L21: =L11-K11 -> 0 | M21: =M11-L11 -> 0 | N21: =N11-M11 -> 0 | O21: =O11-N11 -> 0 | P21: =P11-O11 -> 0 | Q21: =Q11-P11 -> 0 | R21: =R11-Q11 -> 0 | ... X21: =X11-W11 -> 0 | AC21: =+$AN$5+($D$15/100) -> 0.25 | AD21: =+$AN$5+($D$15/100) -> 0.25 | AE21: =+$AN$5+($D$15/100) -> 0.25 | AF21: =+$AN$5+($D$15/100) -> 0.25 | AG21: =+$AN$5+($D$15/100) -> 0.25 | AH21: =+$AN$5+($D$15/100) -> 0.25 | AI21: =+$AN$5+($D$15/100) -> 0.25 | AJ21: =+$AN$5+($D$15/100) -> 0.25 | ... AQ21: =+$AN$5+($D$15/100) -> 0.25
AC23: PL/HA-DATO ORIGEN GRAFICO= | AI23: =IF(B7="",D16,B7) -> 0
AC26: Densidad de siembra | AH26: =B7 -> 0
AC27: Distancia entre surcos | AH27: =D15/100 -> 0
AC28: Distancia eq 10 m2 (m) | AH28: =IF(AH27="","",10/AH27) -> #DIV/0!
J29: Observaciones: | AC29: Semillas/m lineal | AH29: =IF(AH27="","",1*(AH26/1000)/AH28) -> #DIV/0!
AC30: Distancia e/semillas(cm) | AH30: =IF(AH29="","",1/AH29*100) -> #DIV/0!
AC32: Doble (cm) | AH32: =IF(AH30="","",3) -> #DIV/0!
AC33: Fallo (cm) | AH33: =IF(AH27="","",2*AH30) -> #DIV/0!
AC34: Aceptable

Sheet L3
B1: RECUENTOS POR LOTE - MAIZ | AC1: Distanciamiento entre plantas- DATOS DE ORIGEN GRAFICO
B2: Establecimiento: | F2: Fecha: | K2: Estado Fenológico:
AC3: Sector 1 | AG3: Sector 2 | AK3: Sector 3
B4: Potrero: | D4: Dist.med. | E4: Plantas | F4: Desvío | G4: C.V. | H4: Distancias acumuladas entre plantas | AC4: S 1 | AE4: S 2 | AG4: S 1 | AI4: S 2 | AK4: S 1 | AM4: S 2
B5: Sitio: | D5: cm | E5: por ha | F5: plant.cm | J5: 2 | K5: 3 | L5: 4 | M5: 5 | N5: 6 | O5: 7 | P5: 8 | Q5: 9 | R5: 10 | S5: 11 | T5: 12 | U5: 13 | V5: 14 | W5: 15 | X5: 16 | AC5: {=TRANSPOSE(J6:X6)} -> 0 | AD5: 0.25 | AE5: {=TRANSPOSE(J7:X7)} -> 0 | AF5: =+AD5+($D$15/100) -> 0.25 | AG5: {=TRANSPOSE(J8:X8)} -> 0 | AH5: =+AF5+($D$15/100) -> 0.25 | AI5: {=TRANSPOSE(J9:X9)} -> 0 | AJ5: =+AH5+($D$15/100) -> 0.25 | AK5: {=TRANSPOSE(J10:X10)} -> 0 | AL5: =+AJ5+($D$15/100) -> 0.25 | AM5: {=TRANSPOSE(J11:X11)} -> 0 | AN5: =+AL5+($D$15/100) -> 0.25
B6: Densidad de Siembra: | D6: =IF(SUM(J16:X16)=0,0,AVERAGE(J16:X16)) -> 0 | E6: =IF(D6=0,"",100/D6/$D$15*100*10000) | F6: =IF(D6=0,"",STDEV(J16:X16)) | G6: =IF(F6="","",F6/D6) | H6: Sector 1 | I6: Surco 1 | AC6: 0 | AD6: =$AD$5 -> 0.25 | AE6: 0 | AF6: =+AD6+($D$15/100) -> 0.25 | AG6: 0 | AH6: =+AF6+($D$15/100) -> 0.25 | AI6: 0 | AJ6: =+AH6+($D$15/100) -> 0.25 | AK6: 0 | AL6: =+AJ6+($D$15/100) -> 0.25 | AM6: 0 | AN6: =+AL6+($D$15/100) -> 0.25
C7: sem/ha | D7: =IF(SUM(J17:X17)=0,0,AVERAGE(J17:X17)) -> 0 | E7: =IF(D7=0,"",100/D7/$D$15*100*10000) | F7: =IF(D7=0,"",STDEV(J17:X17)) | G7: =IF(F7="","",F7/D7) | I7: Surco 2 | AC7: 0 | AD7: =$AD$5 -> 0.25 | AE7: 0 | AF7: =+AD7+($D$15/100) -> 0.25 | AG7: 0 | AH7: =+AF7+($D$15/100) -> 0.25 | AI7: 0 | AJ7: =+AH7+($D$15/100) -> 0.25 | AK7: 0 | AL7: =+AJ7+($D$15/100) -> 0.25 | AM7: 0 | AN7: =+AL7+($D$15/100) -> 0.25
B8: Antecesor: | D8: =IF(SUM(J18:X18)=0,0,AVERAGE(J18:X18)) -> 0 | E8: =IF(D8=0,"",100/D8/$D$15*100*10000) | F8: =IF(D8=0,"",STDEV(J18:X18)) | G8: =IF(F8="","",F8/D8) | H8: Sector 2 | I8: Surco 1 | AC8: 0 | AD8: =$AD$5 -> 0.25 | AE8: 0 | AF8: =+AD8+($D$15/100) -> 0.25 | AG8: 0 | AH8: =+AF8+($D$15/100) -> 0.25 | AI8: 0 | AJ8: =+AH8+($D$15/100) -> 0.25 | AK8: 0 | AL8: =+AJ8+($D$15/100) -> 0.25 | AM8: 0 | AN8: =+AL8+($D$15/100) -> 0.25
D9: =IF(SUM(J19:X19)=0,0,AVERAGE(J19:X19)) -> 0 | E9: =IF(D9=0,"",100/D9/$D$15*100*10000) | F9: =IF(D9=0,"",STDEV(J19:X19)) | G9: =IF(F9="","",F9/D9) | I9: Surco 2 | AC9: 0 | AD9: =$AD$5 -> 0.25 | AE9: 0 | AF9: =+AD9+($D$15/100) -> 0.25 | AG9: 0 | AH9: =+AF9+($D$15/100) -> 0.25 | AI9: 0 | AJ9: =+AH9+($D$15/100) -> 0.25 | AK9: 0 | AL9: =+AJ9+($D$15/100) -> 0.25 | AM9: 0 | AN9: =+AL9+($D$15/100) -> 0.25
B10: Nombre Contratista: | D10: =IF(SUM(J20:X20)=0,0,AVERAGE(J20:X20)) -> 0 | E10: =IF(D10=0,"",100/D10/$D$15*100*10000) | F10: =IF(D10=0,"",STDEV(J20:X20)) | G10: =IF(F10="","",F10/D10) | H10: Sector 3 | I10: Surco 1 | AC10: 0 | AD10: =$AD$5 -> 0.25 | AE10: 0 | AF10: =+AD10+($D$15/100) -> 0.25 | AG10: 0 | AH10: =+AF10+($D$15/100) -> 0.25 | AI10: 0 | AJ10: =+AH10+($D$15/100) -> 0.25 | AK10: 0 | AL10: =+AJ10+($D$15/100) -> 0.25 | AM10: 0 | AN10: =+AL10+($D$15/100) -> 0.25
D11: =IF(SUM(J21:X21)=0,0,AVERAGE(J21:X21)) -> 0 | E11: =IF(D11=0,"",100/D11/$D$15*100*10000) | F11: =IF(D11=0,"",STDEV(J21:X21)) | G11: =IF(F11="","",F11/D11) | I11: Surco 2 | AC11: 0 | AD11: =$AD$5 -> 0.25 | AE11: 0 | AF11: =+AD11+($D$15/100) -> 0.25 | AG11: 0 | AH11: =+AF11+($D$15/100) -> 0.25 | AI11: 0 | AJ11: =+AH11+($D$15/100) -> 0.25 | AK11: 0 | AL11: =+AJ11+($D$15/100) -> 0.25 | AM11: 0 | AN11: =+AL11+($D$15/100) -> 0.25
B12: Sembradora: | AC12: 0 | AD12: =$AD$5 -> 0.25 | AE12: 0 | AF12: =+AD12+($D$15/100) -> 0.25 | AG12: 0 | AH12: =+AF12+($D$15/100) -> 0.25 | AI12: 0 | AJ12: =+AH12+($D$15/100) -> 0.25 | AK12: 0 | AL12: =+AJ12+($D$15/100) -> 0.25 | AM12: 0 | AN12: =+AL12+($D$15/100) -> 0.25
AC13: 0 | AD13: =$AD$5 -> 0.25 | AE13: 0 | AF13: =+AD13+($D$15/100) -> 0.25 | AG13: 0 | AH13: =+AF13+($D$15/100) -> 0.25 | AI13: 0 | AJ13: =+AH13+($D$15/100) -> 0.25 | AK13: 0 | AL13: =+AJ13+($D$15/100) -> 0.25 | AM13: 0 | AN13: =+AL13+($D$15/100) -> 0.25
D14: =IF(COUNTIF(D6:D13,">0"),SUM(D6:D13)/COUNTIF(D6:D13,">0"),"") | J14: Distancia entre plantas | AC14: 0 | AD14: =$AD$5 -> 0.25 | AE14: 0 | AF14: =+AD14+($D$15/100) -> 0.25 | AG14: 0 | AH14: =+AF14+($D$15/100) -> 0.25 | AI14: 0 | AJ14: =+AH14+($D$15/100) -> 0.25 | AK14: 0 | AL14: =+AJ14+($D$15/100) -> 0.25 | AM14: 0 | AN14: =+AL14+($D$15/100) -> 0.25
B15: Distancia e/surcos (cm) | E15: cm | F15: % Logro | J15: 1-2 | K15: 2-3 | L15: 3-4 | M15: 4-5 | N15: 5-6 | O15: 6-7 | P15: 7-8 | Q15: 8-9 | R15: 9-10 | S15: 10-11 | T15: 11-12 | U15: 12-13 | V15: 13-14 | W15: 14-15 | X15: 15-16 | AC15: 0 | AD15: =$AD$5 -> 0.25 | AE15: 0 | AF15: =+AD15+($D$15/100) -> 0.25 | AG15: 0 | AH15: =+AF15+($D$15/100) -> 0.25 | AI15: 0 | AJ15: =+AH15+($D$15/100) -> 0.25 | AK15: 0 | AL15: =+AJ15+($D$15/100) -> 0.25 | AM15: 0 | AN15: =+AL15+($D$15/100) -> 0.25
B16: Logro promedio de plantas | D16: =IF(SUM(E6:E13)=0,0,AVERAGE(E6:E13)) -> 0 | E16: ptas./ha | F16: =+IF(B7="","",D16/B7*100) | J16: =J6 -> 0 | K16: =K6-J6 -> 0 | L16: =L6-K6 -> 0 | M16: =M6-L6 -> 0 | N16: =N6-M6 -> 0 | O16: =O6-N6 -> 0 | P16: =P6-O6 -> 0 | Q16: =Q6-P6 -> 0 | R16: =R6-Q6 -> 0 | ... X16: =X6-W6 -> 0 | AC16: 0 | AD16: =$AD$5 -> 0.25 | AE16: 0 | AF16: =+AD16+($D$15/100) -> 0.25 | AG16: 0 | AH16: =+AF16+($D$15/100) -> 0.25 | AI16: 0 | AJ16: =+AH16+($D$15/100) -> 0.25 | AK16: 0 | AL16: =+AJ16+($D$15/100) -> 0.25 | AM16: 0 | AN16: =+AL16+($D$15/100) -> 0.25
B17: Desvío uniformidad planteo | D17: =IF(SUM(F6:F13)=0,0,AVERAGE(F6:F13)) -> 0 | E17: cm | J17: =J7 -> 0 | K17: =K7-J7 -> 0 | L17: =L7-K7 -> 0 | M17: =M7-L7 -> 0 | N17: =N7-M7 -> 0 | O17: =O7-N7 -> 0 | P17: =P7-O7 -> 0 | Q17: =Q7-P7 -> 0 | R17: =R7-Q7 -> 0 | ... X17: =X7-W7 -> 0 | AC17: 0 | AD17: =$AD$5 -> 0.25 | AE17: 0 | AF17: =+AD17+($D$15/100) -> 0.25 | AG17: 0 | AH17: =+AF17+($D$15/100) -> 0.25 | AI17: 0 | AJ17: =+AH17+($D$15/100) -> 0.25 | AK17: 0 | AL17: =+AJ17+($D$15/100) -> 0.25 | AM17: 0 | AN17: =+AL17+($D$15/100) -> 0.25
B18: COEFICIENTE DE VARIACIÓN | D18: =IF(SUM(G6:G13)=0,0,AVERAGE(G6:G13)) -> 0 | J18: =J8 -> 0 | K18: =K8-J8 -> 0 | L18: =L8-K8 -> 0 | M18: =M8-L8 -> 0 | N18: =N8-M8 -> 0 | O18: =O8-N8 -> 0 | P18: =P8-O8 -> 0 | Q18: =Q8-P8 -> 0 | R18: =R8-Q8 -> 0 | ... X18: =X8-W8 -> 0
J19: =J9 -> 0 | K19: =K9-J9 -> 0 | L19: =L9-K9 -> 0 | M19: =M9-L9 -> 0 | N19: =N9-M9 -> 0 | O19: =O9-N9 -> 0 | P19: =P9-O9 -> 0 | Q19: =Q9-P9 -> 0 | R19: =R9-Q9 -> 0 | ... X19: =X9-W9 -> 0 | AC19: DISTANCIAMIENTO ENTRE PLANTAS IDEAL-DATOS ORIGEN GRAFICO
B20: Distribución espacial | J20: =J10 -> 0 | K20: =K10-J10 -> 0 | L20: =L10-K10 -> 0 | M20: =M10-L10 -> 0 | N20: =N10-M10 -> 0 | O20: =O10-N10 -> 0 | P20: =P10-O10 -> 0 | Q20: =Q10-P10 -> 0 | R20: =R10-Q10 -> 0 | ... X20: =X10-W10 -> 0 | AC20: =100/(AI23/(100*(100/($D$15/100)))) -> #DIV/0! | AD20: =+$AC$20*J5 -> #DIV/0! | AE20: =+$AC$20*K5 -> #DIV/0! | AF20: =+$AC$20*L5 -> #DIV/0! | AG20: =+$AC$20*M5 -> #DIV/0! | AH20: =+$AC$20*N5 -> #DIV/0! | AI20: =+$AC$20*O5 -> #DIV/0! | AJ20: =+$AC$20*P5 -> #DIV/0! | AK20: =+$AC$20*Q5 -> #DIV/0! | ... AQ20: =+$AC$20*W5 -> #DIV/0!
J21: =J11 -> 0 | K21: =K11-J11 -> 0 | L21: =L11-K11 -> 0 | M21: =M11-L11 -> 0 | N21: =N11-M11 -> 0 | O21: =O11-N11 -> 0 | P21: =P11-O11 -> 0 | Q21: =Q11-P11 -> 0 | R21: =R11-Q11 -> 0 | ... X21: =X11-W11 -> 0 | AC21: =+$AN$5+($D$15/100) -> 0.25 | AD21: =+$AN$5+($D$15/100) -> 0.25 | AE21: =+$AN$5+($D$15/100) -> 0.25 | AF21: =+$AN$5+($D$15/100) -> 0.25 | AG21: =+$AN$5+($D$15/100) -> 0.25 | AH21: =+$AN$5+($D$15/100) -> 0.25 | AI21: =+$AN$5+($D$15/100) -> 0.25 | AJ21: =+$AN$5+($D$15/100) -> 0.25 | ... AQ21: =+$AN$5+($D$15/100) -> 0.25
AC23: PL/HA-DATO ORIGEN GRAFICO= | AI23: =IF(B7="",D16,B7) -> 0
AC26: Densidad de siembra | AH26: =B7 -> 0
AC27: Distancia entre surcos | AH27: =D15/100 -> 0
AC28: Distancia eq 10 m2 (m) | AH28: =IF(AH27="","",10/AH27) -> #DIV/0!
J29: Observaciones: | AC29: Semillas/m lineal | AH29: =IF(AH27="","",1*(AH26/1000)/AH28) -> #DIV/0!
AC30: Distancia e/semillas(cm) | AH30: =IF(AH29="","",1/AH29*100) -> #DIV/0!
AC32: Doble (cm) | AH32: =IF(AH30="","",3) -> #DIV/0!
AC33: Fallo (cm) | AH33: =IF(AH27="","",2*AH30) -> #DIV/0!
AC34: Aceptable

Sheet L4
B1: RECUENTOS POR LOTE - MAIZ | AC1: Distanciamiento entre plantas- DATOS DE ORIGEN GRAFICO
B2: Establecimiento: | F2: Fecha: | K2: Estado Fenológico:
AC3: Sector 1 | AG3: Sector 2 | AK3: Sector 3
B4: Potrero: | D4: Dist.med. | E4: Plantas | F4: Desvío | G4: C.V. | H4: Distancias acumuladas entre plantas | AC4: S 1 | AE4: S 2 | AG4: S 1 | AI4: S 2 | AK4: S 1 | AM4: S 2
B5: Sitio: | D5: cm | E5: por ha | F5: plant.cm | J5: 2 | K5: 3 | L5: 4 | M5: 5 | N5: 6 | O5: 7 | P5: 8 | Q5: 9 | R5: 10 | S5: 11 | T5: 12 | U5: 13 | V5: 14 | W5: 15 | X5: 16 | AC5: {=TRANSPOSE(J6:X6)} -> 0 | AD5: 0.25 | AE5: {=TRANSPOSE(J7:X7)} -> 0 | AF5: =+AD5+($D$15/100) -> 0.25 | AG5: {=TRANSPOSE(J8:X8)} -> 0 | AH5: =+AF5+($D$15/100) -> 0.25 | AI5: {=TRANSPOSE(J9:X9)} -> 0 | AJ5: =+AH5+($D$15/100) -> 0.25 | AK5: {=TRANSPOSE(J10:X10)} -> 0 | AL5: =+AJ5+($D$15/100) -> 0.25 | AM5: {=TRANSPOSE(J11:X11)} -> 0 | AN5: =+AL5+($D$15/100) -> 0.25
B6: Densidad de Siembra: | D6: =IF(SUM(J16:X16)=0,0,AVERAGE(J16:X16)) -> 0 | E6: =IF(D6=0,"",100/D6/$D$15*100*10000) | F6: =IF(D6=0,"",STDEV(J16:X16)) | G6: =IF(F6="","",F6/D6) | H6: Sector 1 | I6: Surco 1 | AC6: 0 | AD6: =$AD$5 -> 0.25 | AE6: 0 | AF6: =+AD6+($D$15/100) -> 0.25 | AG6: 0 | AH6: =+AF6+($D$15/100) -> 0.25 | AI6: 0 | AJ6: =+AH6+($D$15/100) -> 0.25 | AK6: 0 | AL6: =+AJ6+($D$15/100) -> 0.25 | AM6: 0 | AN6: =+AL6+($D$15/100) -> 0.25
C7: sem/ha | D7: =IF(SUM(J17:X17)=0,0,AVERAGE(J17:X17)) -> 0 | E7: =IF(D7=0,"",100/D7/$D$15*100*10000) | F7: =IF(D7=0,"",STDEV(J17:X17)) | G7: =IF(F7="","",F7/D7) | I7: Surco 2 | AC7: 0 | AD7: =$AD$5 -> 0.25 | AE7: 0 | AF7: =+AD7+($D$15/100) -> 0.25 | AG7: 0 | AH7: =+AF7+($D$15/100) -> 0.25 | AI7: 0 | AJ7: =+AH7+($D$15/100) -> 0.25 | AK7: 0 | AL7: =+AJ7+($D$15/100) -> 0.25 | AM7: 0 | AN7: =+AL7+($D$15/100) -> 0.25
B8: Antecesor: | D8: =IF(SUM(J18:X18)=0,0,AVERAGE(J18:X18)) -> 0 | E8: =IF(D8=0,"",100/D8/$D$15*100*10000) | F8: =IF(D8=0,"",STDEV(J18:X18)) | G8: =IF(F8="","",F8/D8) | H8: Sector 2 | I8: Surco 1 | AC8: 0 | AD8: =$AD$5 -> 0.25 | AE8: 0 | AF8: =+AD8+($D$15/100) -> 0.25 | AG8: 0 | AH8: =+AF8+($D$15/100) -> 0.25 | AI8: 0 | AJ8: =+AH8+($D$15/100) -> 0.25 | AK8: 0 | AL8: =+AJ8+($D$15/100) -> 0.25 | AM8: 0 | AN8: =+AL8+($D$15/100) -> 0.25
D9: =IF(SUM(J19:X19)=0,0,AVERAGE(J19:X19)) -> 0 | E9: =IF(D9=0,"",100/D9/$D$15*100*10000) | F9: =IF(D9=0,"",STDEV(J19:X19)) | G9: =IF(F9="","",F9/D9) | I9: Surco 2 | AC9: 0 | AD9: =$AD$5 -> 0.25 | AE9: 0 | AF9: =+AD9+($D$15/100) -> 0.25 | AG9: 0 | AH9: =+AF9+($D$15/100) -> 0.25 | AI9: 0 | AJ9: =+AH9+($D$15/100) -> 0.25 | AK9: 0 | AL9: =+AJ9+($D$15/100) -> 0.25 | AM9: 0 | AN9: =+AL9+($D$15/100) -> 0.25
B10: Nombre Contratista: | D10: =IF(SUM(J20:X20)=0,0,AVERAGE(J20:X20)) -> 0 | E10: =IF(D10=0,"",100/D10/$D$15*100*10000) | F10: =IF(D10=0,"",STDEV(J20:X20)) | G10: =IF(F10="","",F10/D10) | H10: Sector 3 | I10: Surco 1 | AC10: 0 | AD10: =$AD$5 -> 0.25 | AE10: 0 | AF10: =+AD10+($D$15/100) -> 0.25 | AG10: 0 | AH10: =+AF10+($D$15/100) -> 0.25 | AI10: 0 | AJ10: =+AH10+($D$15/100) -> 0.25 | AK10: 0 | AL10: =+AJ10+($D$15/100) -> 0.25 | AM10: 0 | AN10: =+AL10+($D$15/100) -> 0.25
D11: =IF(SUM(J21:X21)=0,0,AVERAGE(J21:X21)) -> 0 | E11: =IF(D11=0,"",100/D11/$D$15*100*10000) | F11: =IF(D11=0,"",STDEV(J21:X21)) | G11: =IF(F11="","",F11/D11) | I11: Surco 2 | AC11: 0 | AD11: =$AD$5 -> 0.25 | AE11: 0 | AF11: =+AD11+($D$15/100) -> 0.25 | AG11: 0 | AH11: =+AF11+($D$15/100) -> 0.25 | AI11: 0 | AJ11: =+AH11+($D$15/100) -> 0.25 | AK11: 0 | AL11: =+AJ11+($D$15/100) -> 0.25 | AM11: 0 | AN11: =+AL11+($D$15/100) -> 0.25
B12: Sembradora: | AC12: 0 | AD12: =$AD$5 -> 0.25 | AE12: 0 | AF12: =+AD12+($D$15/100) -> 0.25 | AG12: 0 | AH12: =+AF12+($D$15/100) -> 0.25 | AI12: 0 | AJ12: =+AH12+($D$15/100) -> 0.25 | AK12: 0 | AL12: =+AJ12+($D$15/100) -> 0.25 | AM12: 0 | AN12: =+AL12+($D$15/100) -> 0.25
AC13: 0 | AD13: =$AD$5 -> 0.25 | AE13: 0 | AF13: =+AD13+($D$15/100) -> 0.25 | AG13: 0 | AH13: =+AF13+($D$15/100) -> 0.25 | AI13: 0 | AJ13: =+AH13+($D$15/100) -> 0.25 | AK13: 0 | AL13: =+AJ13+($D$15/100) -> 0.25 | AM13: 0 | AN13: =+AL13+($D$15/100) -> 0.25
D14: =IF(COUNTIF(D6:D13,">0"),SUM(D6:D13)/COUNTIF(D6:D13,">0"),"") | J14: Distancia entre plantas | AC14: 0 | AD14: =$AD$5 -> 0.25 | AE14: 0 | AF14: =+AD14+($D$15/100) -> 0.25 | AG14: 0 | AH14: =+AF14+($D$15/100) -> 0.25 | AI14: 0 | AJ14: =+AH14+($D$15/100) -> 0.25 | AK14: 0 | AL14: =+AJ14+($D$15/100) -> 0.25 | AM14: 0 | AN14: =+AL14+($D$15/100) -> 0.25
B15: Distancia e/surcos (cm) | E15: cm | F15: % Logro | J15: 1-2 | K15: 2-3 | L15: 3-4 | M15: 4-5 | N15: 5-6 | O15: 6-7 | P15: 7-8 | Q15: 8-9 | R15: 9-10 | S15: 10-11 | T15: 11-12 | U15: 12-13 | V15: 13-14 | W15: 14-15 | X15: 15-16 | AC15: 0 | AD15: =$AD$5 -> 0.25 | AE15: 0 | AF15: =+AD15+($D$15/100) -> 0.25 | AG15: 0 | AH15: =+AF15+($D$15/100) -> 0.25 | AI15: 0 | AJ15: =+AH15+($D$15/100) -> 0.25 | AK15: 0 | AL15: =+AJ15+($D$15/100) -> 0.25 | AM15: 0 | AN15: =+AL15+($D$15/100) -> 0.25
B16: Logro promedio de plantas | D16: =IF(SUM(E6:E13)=0,0,AVERAGE(E6:E13)) -> 0 | E16: ptas./ha | F16: =+IF(B7="","",D16/B7*100) | J16: =J6 -> 0 | K16: =K6-J6 -> 0 | L16: =L6-K6 -> 0 | M16: =M6-L6 -> 0 | N16: =N6-M6 -> 0 | O16: =O6-N6 -> 0 | P16: =P6-O6 -> 0 | Q16: =Q6-P6 -> 0 | R16: =R6-Q6 -> 0 | ... X16: =X6-W6 -> 0 | AC16: 0 | AD16: =$AD$5 -> 0.25 | AE16: 0 | AF16: =+AD16+($D$15/100) -> 0.25 | AG16: 0 | AH16: =+AF16+($D$15/100) -> 0.25 | AI16: 0 | AJ16: =+AH16+($D$15/100) -> 0.25 | AK16: 0 | AL16: =+AJ16+($D$15/100) -> 0.25 | AM16: 0 | AN16: =+AL16+($D$15/100) -> 0.25
B17: Desvío uniformidad planteo | D17: =IF(SUM(F6:F13)=0,0,AVERAGE(F6:F13)) -> 0 | E17: cm | J17: =J7 -> 0 | K17: =K7-J7 -> 0 | L17: =L7-K7 -> 0 | M17: =M7-L7 -> 0 | N17: =N7-M7 -> 0 | O17: =O7-N7 -> 0 | P17: =P7-O7 -> 0 | Q17: =Q7-P7 -> 0 | R17: =R7-Q7 -> 0 | ... X17: =X7-W7 -> 0 | AC17: 0 | AD17: =$AD$5 -> 0.25 | AE17: 0 | AF17: =+AD17+($D$15/100) -> 0.25 | AG17: 0 | AH17: =+AF17+($D$15/100) -> 0.25 | AI17: 0 | AJ17: =+AH17+($D$15/100) -> 0.25 | AK17: 0 | AL17: =+AJ17+($D$15/100) -> 0.25 | AM17: 0 | AN17: =+AL17+($D$15/100) -> 0.25
B18: COEFICIENTE DE VARIACIÓN | D18: =IF(SUM(G6:G13)=0,0,AVERAGE(G6:G13)) -> 0 | J18: =J8 -> 0 | K18: =K8-J8 -> 0 | L18: =L8-K8 -> 0 | M18: =M8-L8 -> 0 | N18: =N8-M8 -> 0 | O18: =O8-N8 -> 0 | P18: =P8-O8 -> 0 | Q18: =Q8-P8 -> 0 | R18: =R8-Q8 -> 0 | ... X18: =X8-W8 -> 0
J19: =J9 -> 0 | K19: =K9-J9 -> 0 | L19: =L9-K9 -> 0 | M19: =M9-L9 -> 0 | N19: =N9-M9 -> 0 | O19: =O9-N9 -> 0 | P19: =P9-O9 -> 0 | Q19: =Q9-P9 -> 0 | R19: =R9-Q9 -> 0 | ... X19: =X9-W9 -> 0 | AC19: DISTANCIAMIENTO ENTRE PLANTAS IDEAL-DATOS ORIGEN GRAFICO
B20: Distribución espacial | J20: =J10 -> 0 | K20: =K10-J10 -> 0 | L20: =L10-K10 -> 0 | M20: =M10-L10 -> 0 | N20: =N10-M10 -> 0 | O20: =O10-N10 -> 0 | P20: =P10-O10 -> 0 | Q20: =Q10-P10 -> 0 | R20: =R10-Q10 -> 0 | ... X20: =X10-W10 -> 0 | AC20: =100/(AI23/(100*(100/($D$15/100)))) -> #DIV/0! | AD20: =+$AC$20*J5 -> #DIV/0! | AE20: =+$AC$20*K5 -> #DIV/0! | AF20: =+$AC$20*L5 -> #DIV/0! | AG20: =+$AC$20*M5 -> #DIV/0! | AH20: =+$AC$20*N5 -> #DIV/0! | AI20: =+$AC$20*O5 -> #DIV/0! | AJ20: =+$AC$20*P5 -> #DIV/0! | AK20: =+$AC$20*Q5 -> #DIV/0! | ... AQ20: =+$AC$20*W5 -> #DIV/0!
J21: =J11 -> 0 | K21: =K11-J11 -> 0 | L21: =L11-K11 -> 0 | M21: =M11-L11 -> 0 | N21: =N11-M11 -> 0 | O21: =O11-N11 -> 0 | P21: =P11-O11 -> 0 | Q21: =Q11-P11 -> 0 | R21: =R11-Q11 -> 0 | ... X21: =X11-W11 -> 0 | AC21: =+$AN$5+($D$15/100) -> 0.25 | AD21: =+$AN$5+($D$15/100) -> 0.25 | AE21: =+$AN$5+($D$15/100) -> 0.25 | AF21: =+$AN$5+($D$15/100) -> 0.25 | AG21: =+$AN$5+($D$15/100) -> 0.25 | AH21: =+$AN$5+($D$15/100) -> 0.25 | AI21: =+$AN$5+($D$15/100) -> 0.25 | AJ21: =+$AN$5+($D$15/100) -> 0.25 | ... AQ21: =+$AN$5+($D$15/100) -> 0.25
AC23: PL/HA-DATO ORIGEN GRAFICO= | AI23: =IF(B7="",D16,B7) -> 0
AC26: Densidad de siembra | AH26: =B7 -> 0
AC27: Distancia entre surcos | AH27: =D15/100 -> 0
AC28: Distancia eq 10 m2 (m) | AH28: =IF(AH27="","",10/AH27) -> #DIV/0!
J29: Observaciones: | AC29: Semillas/m lineal | AH29: =IF(AH27="","",1*(AH26/1000)/AH28) -> #DIV/0!
AC30: Distancia e/semillas(cm) | AH30: =IF(AH29="","",1/AH29*100) -> #DIV/0!
AC32: Doble (cm) | AH32: =IF(AH30="","",3) -> #DIV/0!
AC33: Fallo (cm) | AH33: =IF(AH27="","",2*AH30) -> #DIV/0!
AC34: Aceptable

Sheet L5
B1: RECUENTOS POR LOTE - MAIZ | AC1: Distanciamiento entre plantas- DATOS DE ORIGEN GRAFICO
B2: Establecimiento: | F2: Fecha: | K2: Estado Fenológico:
AC3: Sector 1 | AG3: Sector 2 | AK3: Sector 3
B4: Potrero: | D4: Dist.med. | E4: Plantas | F4: Desvío | G4: C.V. | H4: Distancias acumuladas entre plantas | AC4: S 1 | AE4: S 2 | AG4: S 1 | AI4: S 2 | AK4: S 1 | AM4: S 2
B5: Sitio: | D5: cm | E5: por ha | F5: plant.cm | J5: 2 | K5: 3 | L5: 4 | M5: 5 | N5: 6 | O5: 7 | P5: 8 | Q5: 9 | R5: 10 | S5: 11 | T5: 12 | U5: 13 | V5: 14 | W5: 15 | X5: 16 | AC5: {=TRANSPOSE(J6:X6)} -> 0 | AD5: 0.25 | AE5: {=TRANSPOSE(J7:X7)} -> 0 | AF5: =+AD5+($D$15/100) -> 0.25 | AG5: {=TRANSPOSE(J8:X8)} -> 0 | AH5: =+AF5+($D$15/100) -> 0.25 | AI5: {=TRANSPOSE(J9:X9)} -> 0 | AJ5: =+AH5+($D$15/100) -> 0.25 | AK5: {=TRANSPOSE(J10:X10)} -> 0 | AL5: =+AJ5+($D$15/100) -> 0.25 | AM5: {=TRANSPOSE(J11:X11)} -> 0 | AN5: =+AL5+($D$15/100) -> 0.25
B6: Densidad de Siembra: | D6: =IF(SUM(J16:X16)=0,0,AVERAGE(J16:X16)) -> 0 | E6: =IF(D6=0,"",100/D6/$D$15*100*10000) | F6: =IF(D6=0,"",STDEV(J16:X16)) | G6: =IF(F6="","",F6/D6) | H6: Sector 1 | I6: Surco 1 | AC6: 0 | AD6: =$AD$5 -> 0.25 | AE6: 0 | AF6: =+AD6+($D$15/100) -> 0.25 | AG6: 0 | AH6: =+AF6+($D$15/100) -> 0.25 | AI6: 0 | AJ6: =+AH6+($D$15/100) -> 0.25 | AK6: 0 | AL6: =+AJ6+($D$15/100) -> 0.25 | AM6: 0 | AN6: =+AL6+($D$15/100) -> 0.25
C7: sem/ha | D7: =IF(SUM(J17:X17)=0,0,AVERAGE(J17:X17)) -> 0 | E7: =IF(D7=0,"",100/D7/$D$15*100*10000) | F7: =IF(D7=0,"",STDEV(J17:X17)) | G7: =IF(F7="","",F7/D7) | I7: Surco 2 | AC7: 0 | AD7: =$AD$5 -> 0.25 | AE7: 0 | AF7: =+AD7+($D$15/100) -> 0.25 | AG7: 0 | AH7: =+AF7+($D$15/100) -> 0.25 | AI7: 0 | AJ7: =+AH7+($D$15/100) -> 0.25 | AK7: 0 | AL7: =+AJ7+($D$15/100) -> 0.25 | AM7: 0 | AN7: =+AL7+($D$15/100) -> 0.25
B8: Antecesor: | D8: =IF(SUM(J18:X18)=0,0,AVERAGE(J18:X18)) -> 0 | E8: =IF(D8=0,"",100/D8/$D$15*100*10000) | F8: =IF(D8=0,"",STDEV(J18:X18)) | G8: =IF(F8="","",F8/D8) | H8: Sector 2 | I8: Surco 1 | AC8: 0 | AD8: =$AD$5 -> 0.25 | AE8: 0 | AF8: =+AD8+($D$15/100) -> 0.25 | AG8: 0 | AH8: =+AF8+($D$15/100) -> 0.25 | AI8: 0 | AJ8: =+AH8+($D$15/100) -> 0.25 | AK8: 0 | AL8: =+AJ8+($D$15/100) -> 0.25 | AM8: 0 | AN8: =+AL8+($D$15/100) -> 0.25
D9: =IF(SUM(J19:X19)=0,0,AVERAGE(J19:X19)) -> 0 | E9: =IF(D9=0,"",100/D9/$D$15*100*10000) | F9: =IF(D9=0,"",STDEV(J19:X19)) | G9: =IF(F9="","",F9/D9) | I9: Surco 2 | AC9: 0 | AD9: =$AD$5 -> 0.25 | AE9: 0 | AF9: =+AD9+($D$15/100) -> 0.25 | AG9: 0 | AH9: =+AF9+($D$15/100) -> 0.25 | AI9: 0 | AJ9: =+AH9+($D$15/100) -> 0.25 | AK9: 0 | AL9: =+AJ9+($D$15/100) -> 0.25 | AM9: 0 | AN9: =+AL9+($D$15/100) -> 0.25
B10: Nombre Contratista: | D10: =IF(SUM(J20:X20)=0,0,AVERAGE(J20:X20)) -> 0 | E10: =IF(D10=0,"",100/D10/$D$15*100*10000) | F10: =IF(D10=0,"",STDEV(J20:X20)) | G10: =IF(F10="","",F10/D10) | H10: Sector 3 | I10: Surco 1 | AC10: 0 | AD10: =$AD$5 -> 0.25 | AE10: 0 | AF10: =+AD10+($D$15/100) -> 0.25 | AG10: 0 | AH10: =+AF10+($D$15/100) -> 0.25 | AI10: 0 | AJ10: =+AH10+($D$15/100) -> 0.25 | AK10: 0 | AL10: =+AJ10+($D$15/100) -> 0.25 | AM10: 0 | AN10: =+AL10+($D$15/100) -> 0.25
D11: =IF(SUM(J21:X21)=0,0,AVERAGE(J21:X21)) -> 0 | E11: =IF(D11=0,"",100/D11/$D$15*100*10000) | F11: =IF(D11=0,"",STDEV(J21:X21)) | G11: =IF(F11="","",F11/D11) | I11: Surco 2 | AC11: 0 | AD11: =$AD$5 -> 0.25 | AE11: 0 | AF11: =+AD11+($D$15/100) -> 0.25 | AG11: 0 | AH11: =+AF11+($D$15/100) -> 0.25 | AI11: 0 | AJ11: =+AH11+($D$15/100) -> 0.25 | AK11: 0 | AL11: =+AJ11+($D$15/100) -> 0.25 | AM11: 0 | AN11: =+AL11+($D$15/100) -> 0.25
B12: Sembradora: | AC12: 0 | AD12: =$AD$5 -> 0.25 | AE12: 0 | AF12: =+AD12+($D$15/100) -> 0.25 | AG12: 0 | AH12: =+AF12+($D$15/100) -> 0.25 | AI12: 0 | AJ12: =+AH12+($D$15/100) -> 0.25 | AK12: 0 | AL12: =+AJ12+($D$15/100) -> 0.25 | AM12: 0 | AN12: =+AL12+($D$15/100) -> 0.25
AC13: 0 | AD13: =$AD$5 -> 0.25 | AE13: 0 | AF13: =+AD13+($D$15/100) -> 0.25 | AG13: 0 | AH13: =+AF13+($D$15/100) -> 0.25 | AI13: 0 | AJ13: =+AH13+($D$15/100) -> 0.25 | AK13: 0 | AL13: =+AJ13+($D$15/100) -> 0.25 | AM13: 0 | AN13: =+AL13+($D$15/100) -> 0.25
D14: =IF(COUNTIF(D6:D13,">0"),SUM(D6:D13)/COUNTIF(D6:D13,">0"),"") | J14: Distancia entre plantas | AC14: 0 | AD14: =$AD$5 -> 0.25 | AE14: 0 | AF14: =+AD14+($D$15/100) -> 0.25 | AG14: 0 | AH14: =+AF14+($D$15/100) -> 0.25 | AI14: 0 | AJ14: =+AH14+($D$15/100) -> 0.25 | AK14: 0 | AL14: =+AJ14+($D$15/100) -> 0.25 | AM14: 0 | AN14: =+AL14+($D$15/100) -> 0.25
B15: Distancia e/surcos (cm) | E15: cm | F15: % Logro | J15: 1-2 | K15: 2-3 | L15: 3-4 | M15: 4-5 | N15: 5-6 | O15: 6-7 | P15: 7-8 | Q15: 8-9 | R15: 9-10 | S15: 10-11 | T15: 11-12 | U15: 12-13 | V15: 13-14 | W15: 14-15 | X15: 15-16 | AC15: 0 | AD15: =$AD$5 -> 0.25 | AE15: 0 | AF15: =+AD15+($D$15/100) -> 0.25 | AG15: 0 | AH15: =+AF15+($D$15/100) -> 0.25 | AI15: 0 | AJ15: =+AH15+($D$15/100) -> 0.25 | AK15: 0 | AL15: =+AJ15+($D$15/100) -> 0.25 | AM15: 0 | AN15: =+AL15+($D$15/100) -> 0.25
B16: Logro promedio de plantas | D16: =IF(SUM(E6:E13)=0,0,AVERAGE(E6:E13)) -> 0 | E16: ptas./ha | F16: =+IF(B7="","",D16/B7*100) | J16: =J6 -> 0 | K16: =K6-J6 -> 0 | L16: =L6-K6 -> 0 | M16: =M6-L6 -> 0 | N16: =N6-M6 -> 0 | O16: =O6-N6 -> 0 | P16: =P6-O6 -> 0 | Q16: =Q6-P6 -> 0 | R16: =R6-Q6 -> 0 | ... X16: =X6-W6 -> 0 | AC16: 0 | AD16: =$AD$5 -> 0.25 | AE16: 0 | AF16: =+AD16+($D$15/100) -> 0.25 | AG16: 0 | AH16: =+AF16+($D$15/100) -> 0.25 | AI16: 0 | AJ16: =+AH16+($D$15/100) -> 0.25 | AK16: 0 | AL16: =+AJ16+($D$15/100) -> 0.25 | AM16: 0 | AN16: =+AL16+($D$15/100) -> 0.25
B17: Desvío uniformidad planteo | D17: =IF(SUM(F6:F13)=0,0,AVERAGE(F6:F13)) -> 0 | E17: cm | J17: =J7 -> 0 | K17: =K7-J7 -> 0 | L17: =L7-K7 -> 0 | M17: =M7-L7 -> 0 | N17: =N7-M7 -> 0 | O17: =O7-N7 -> 0 | P17: =P7-O7 -> 0 | Q17: =Q7-P7 -> 0 | R17: =R7-Q7 -> 0 | ... X17: =X7-W7 -> 0 | AC17: 0 | AD17: =$AD$5 -> 0.25 | AE17: 0 | AF17: =+AD17+($D$15/100) -> 0.25 | AG17: 0 | AH17: =+AF17+($D$15/100) -> 0.25 | AI17: 0 | AJ17: =+AH17+($D$15/100) -> 0.25 | AK17: 0 | AL17: =+AJ17+($D$15/100) -> 0.25 | AM17: 0 | AN17: =+AL17+($D$15/100) -> 0.25
B18: COEFICIENTE DE VARIACIÓN | D18: =IF(SUM(G6:G13)=0,0,AVERAGE(G6:G13)) -> 0 | J18: =J8 -> 0 | K18: =K8-J8 -> 0 | L18: =L8-K8 -> 0 | M18: =M8-L8 -> 0 | N18: =N8-M8 -> 0 | O18: =O8-N8 -> 0 | P18: =P8-O8 -> 0 | Q18: =Q8-P8 -> 0 | R18: =R8-Q8 -> 0 | ... X18: =X8-W8 -> 0
J19: =J9 -> 0 | K19: =K9-J9 -> 0 | L19: =L9-K9 -> 0 | M19: =M9-L9 -> 0 | N19: =N9-M9 -> 0 | O19: =O9-N9 -> 0 | P19: =P9-O9 -> 0 | Q19: =Q9-P9 -> 0 | R19: =R9-Q9 -> 0 | ... X19: =X9-W9 -> 0 | AC19: DISTANCIAMIENTO ENTRE PLANTAS IDEAL-DATOS ORIGEN GRAFICO
B20: Distribución espacial | J20: =J10 -> 0 | K20: =K10-J10 -> 0 | L20: =L10-K10 -> 0 | M20: =M10-L10 -> 0 | N20: =N10-M10 -> 0 | O20: =O10-N10 -> 0 | P20: =P10-O10 -> 0 | Q20: =Q10-P10 -> 0 | R20: =R10-Q10 -> 0 | ... X20: =X10-W10 -> 0 | AC20: =100/(AI23/(100*(100/($D$15/100)))) -> #DIV/0! | AD20: =+$AC$20*J5 -> #DIV/0! | AE20: =+$AC$20*K5 -> #DIV/0! | AF20: =+$AC$20*L5 -> #DIV/0! | AG20: =+$AC$20*M5 -> #DIV/0! | AH20: =+$AC$20*N5 -> #DIV/0! | AI20: =+$AC$20*O5 -> #DIV/0! | AJ20: =+$AC$20*P5 -> #DIV/0! | AK20: =+$AC$20*Q5 -> #DIV/0! | ... AQ20: =+$AC$20*W5 -> #DIV/0!
J21: =J11 -> 0 | K21: =K11-J11 -> 0 | L21: =L11-K11 -> 0 | M21: =M11-L11 -> 0 | N21: =N11-M11 -> 0 | O21: =O11-N11 -> 0 | P21: =P11-O11 -> 0 | Q21: =Q11-P11 -> 0 | R21: =R11-Q11 -> 0 | ... X21: =X11-W11 -> 0 | AC21: =+$AN$5+($D$15/100) -> 0.25 | AD21: =+$AN$5+($D$15/100) -> 0.25 | AE21: =+$AN$5+($D$15/100) -> 0.25 | AF21: =+$AN$5+($D$15/100) -> 0.25 | AG21: =+$AN$5+($D$15/100) -> 0.25 | AH21: =+$AN$5+($D$15/100) -> 0.25 | AI21: =+$AN$5+($D$15/100) -> 0.25 | AJ21: =+$AN$5+($D$15/100) -> 0.25 | ... AQ21: =+$AN$5+($D$15/100) -> 0.25
AC23: PL/HA-DATO ORIGEN GRAFICO= | AI23: =IF(B7="",D16,B7) -> 0
AC26: Densidad de siembra | AH26: =B7 -> 0
AC27: Distancia entre surcos | AH27: =D15/100 -> 0
AC28: Distancia eq 10 m2 (m) | AH28: =IF(AH27="","",10/AH27) -> #DIV/0!
J29: Observaciones: | AC29: Semillas/m lineal | AH29: =IF(AH27="","",1*(AH26/1000)/AH28) -> #DIV/0!
AC30: Distancia e/semillas(cm) | AH30: =IF(AH29="","",1/AH29*100) -> #DIV/0!
AC32: Doble (cm) | AH32: =IF(AH30="","",3) -> #DIV/0!
AC33: Fallo (cm) | AH33: =IF(AH27="","",2*AH30) -> #DIV/0!
AC34: Aceptable

Sheet L6
B1: RECUENTOS POR LOTE - MAIZ | AC1: Distanciamiento entre plantas- DATOS DE ORIGEN GRAFICO
B2: Establecimiento: | F2: Fecha: | K2: Estado Fenológico:
AC3: Sector 1 | AG3: Sector 2 | AK3: Sector 3
B4: Potrero: | D4: Dist.med. | E4: Plantas | F4: Desvío | G4: C.V. | H4: Distancias acumuladas entre plantas | AC4: S 1 | AE4: S 2 | AG4: S 1 | AI4: S 2 | AK4: S 1 | AM4: S 2
B5: Sitio: | D5: cm | E5: por ha | F5: plant.cm | J5: 2 | K5: 3 | L5: 4 | M5: 5 | N5: 6 | O5: 7 | P5: 8 | Q5: 9 | R5: 10 | S5: 11 | T5: 12 | U5: 13 | V5: 14 | W5: 15 | X5: 16 | AC5: {=TRANSPOSE(J6:X6)} -> 0 | AD5: 0.25 | AE5: {=TRANSPOSE(J7:X7)} -> 0 | AF5: =+AD5+($D$15/100) -> 0.25 | AG5: {=TRANSPOSE(J8:X8)} -> 0 | AH5: =+AF5+($D$15/100) -> 0.25 | AI5: {=TRANSPOSE(J9:X9)} -> 0 | AJ5: =+AH5+($D$15/100) -> 0.25 | AK5: {=TRANSPOSE(J10:X10)} -> 0 | AL5: =+AJ5+($D$15/100) -> 0.25 | AM5: {=TRANSPOSE(J11:X11)} -> 0 | AN5: =+AL5+($D$15/100) -> 0.25
B6: Densidad de Siembra: | D6: =IF(SUM(J16:X16)=0,0,AVERAGE(J16:X16)) -> 0 | E6: =IF(D6=0,"",100/D6/$D$15*100*10000) | F6: =IF(D6=0,"",STDEV(J16:X16)) | G6: =IF(F6="","",F6/D6) | H6: Sector 1 | I6: Surco 1 | AC6: 0 | AD6: =$AD$5 -> 0.25 | AE6: 0 | AF6: =+AD6+($D$15/100) -> 0.25 | AG6: 0 | AH6: =+AF6+($D$15/100) -> 0.25 | AI6: 0 | AJ6: =+AH6+($D$15/100) -> 0.25 | AK6: 0 | AL6: =+AJ6+($D$15/100) -> 0.25 | AM6: 0 | AN6: =+AL6+($D$15/100) -> 0.25
C7: sem/ha | D7: =IF(SUM(J17:X17)=0,0,AVERAGE(J17:X17)) -> 0 | E7: =IF(D7=0,"",100/D7/$D$15*100*10000) | F7: =IF(D7=0,"",STDEV(J17:X17)) | G7: =IF(F7="","",F7/D7) | I7: Surco 2 | AC7: 0 | AD7: =$AD$5 -> 0.25 | AE7: 0 | AF7: =+AD7+($D$15/100) -> 0.25 | AG7: 0 | AH7: =+AF7+($D$15/100) -> 0.25 | AI7: 0 | AJ7: =+AH7+($D$15/100) -> 0.25 | AK7: 0 | AL7: =+AJ7+($D$15/100) -> 0.25 | AM7: 0 | AN7: =+AL7+($D$15/100) -> 0.25
B8: Antecesor: | D8: =IF(SUM(J18:X18)=0,0,AVERAGE(J18:X18)) -> 0 | E8: =IF(D8=0,"",100/D8/$D$15*100*10000) | F8: =IF(D8=0,"",STDEV(J18:X18)) | G8: =IF(F8="","",F8/D8) | H8: Sector 2 | I8: Surco 1 | AC8: 0 | AD8: =$AD$5 -> 0.25 | AE8: 0 | AF8: =+AD8+($D$15/100) -> 0.25 | AG8: 0 | AH8: =+AF8+($D$15/100) -> 0.25 | AI8: 0 | AJ8: =+AH8+($D$15/100) -> 0.25 | AK8: 0 | AL8: =+AJ8+($D$15/100) -> 0.25 | AM8: 0 | AN8: =+AL8+($D$15/100) -> 0.25
D9: =IF(SUM(J19:X19)=0,0,AVERAGE(J19:X19)) -> 0 | E9: =IF(D9=0,"",100/D9/$D$15*100*10000) | F9: =IF(D9=0,"",STDEV(J19:X19)) | G9: =IF(F9="","",F9/D9) | I9: Surco 2 | AC9: 0 | AD9: =$AD$5 -> 0.25 | AE9: 0 | AF9: =+AD9+($D$15/100) -> 0.25 | AG9: 0 | AH9: =+AF9+($D$15/100) -> 0.25 | AI9: 0 | AJ9: =+AH9+($D$15/100) -> 0.25 | AK9: 0 | AL9: =+AJ9+($D$15/100) -> 0.25 | AM9: 0 | AN9: =+AL9+($D$15/100) -> 0.25
B10: Nombre Contratista: | D10: =IF(SUM(J20:X20)=0,0,AVERAGE(J20:X20)) -> 0 | E10: =IF(D10=0,"",100/D10/$D$15*100*10000) | F10: =IF(D10=0,"",STDEV(J20:X20)) | G10: =IF(F10="","",F10/D10) | H10: Sector 3 | I10: Surco 1 | AC10: 0 | AD10: =$AD$5 -> 0.25 | AE10: 0 | AF10: =+AD10+($D$15/100) -> 0.25 | AG10: 0 | AH10: =+AF10+($D$15/100) -> 0.25 | AI10: 0 | AJ10: =+AH10+($D$15/100) -> 0.25 | AK10: 0 | AL10: =+AJ10+($D$15/100) -> 0.25 | AM10: 0 | AN10: =+AL10+($D$15/100) -> 0.25
D11: =IF(SUM(J21:X21)=0,0,AVERAGE(J21:X21)) -> 0 | E11: =IF(D11=0,"",100/D11/$D$15*100*10000) | F11: =IF(D11=0,"",STDEV(J21:X21)) | G11: =IF(F11="","",F11/D11) | I11: Surco 2 | AC11: 0 | AD11: =$AD$5 -> 0.25 | AE11: 0 | AF11: =+AD11+($D$15/100) -> 0.25 | AG11: 0 | AH11: =+AF11+($D$15/100) -> 0.25 | AI11: 0 | AJ11: =+AH11+($D$15/100) -> 0.25 | AK11: 0 | AL11: =+AJ11+($D$15/100) -> 0.25 | AM11: 0 | AN11: =+AL11+($D$15/100) -> 0.25
B12: Sembradora: | AC12: 0 | AD12: =$AD$5 -> 0.25 | AE12: 0 | AF12: =+AD12+($D$15/100) -> 0.25 | AG12: 0 | AH12: =+AF12+($D$15/100) -> 0.25 | AI12: 0 | AJ12: =+AH12+($D$15/100) -> 0.25 | AK12: 0 | AL12: =+AJ12+($D$15/100) -> 0.25 | AM12: 0 | AN12: =+AL12+($D$15/100) -> 0.25
AC13: 0 | AD13: =$AD$5 -> 0.25 | AE13: 0 | AF13: =+AD13+($D$15/100) -> 0.25 | AG13: 0 | AH13: =+AF13+($D$15/100) -> 0.25 | AI13: 0 | AJ13: =+AH13+($D$15/100) -> 0.25 | AK13: 0 | AL13: =+AJ13+($D$15/100) -> 0.25 | AM13: 0 | AN13: =+AL13+($D$15/100) -> 0.25
D14: =IF(COUNTIF(D6:D13,">0"),SUM(D6:D13)/COUNTIF(D6:D13,">0"),"") | J14: Distancia entre plantas | AC14: 0 | AD14: =$AD$5 -> 0.25 | AE14: 0 | AF14: =+AD14+($D$15/100) -> 0.25 | AG14: 0 | AH14: =+AF14+($D$15/100) -> 0.25 | AI14: 0 | AJ14: =+AH14+($D$15/100) -> 0.25 | AK14: 0 | AL14: =+AJ14+($D$15/100) -> 0.25 | AM14: 0 | AN14: =+AL14+($D$15/100) -> 0.25
B15: Distancia e/surcos (cm) | E15: cm | F15: % Logro | J15: 1-2 | K15: 2-3 | L15: 3-4 | M15: 4-5 | N15: 5-6 | O15: 6-7 | P15: 7-8 | Q15: 8-9 | R15: 9-10 | S15: 10-11 | T15: 11-12 | U15: 12-13 | V15: 13-14 | W15: 14-15 | X15: 15-16 | AC15: 0 | AD15: =$AD$5 -> 0.25 | AE15: 0 | AF15: =+AD15+($D$15/100) -> 0.25 | AG15: 0 | AH15: =+AF15+($D$15/100) -> 0.25 | AI15: 0 | AJ15: =+AH15+($D$15/100) -> 0.25 | AK15: 0 | AL15: =+AJ15+($D$15/100) -> 0.25 | AM15: 0 | AN15: =+AL15+($D$15/100) -> 0.25
B16: Logro promedio de plantas | D16: =IF(SUM(E6:E13)=0,0,AVERAGE(E6:E13)) -> 0 | E16: ptas./ha | F16: =+IF(B7="","",D16/B7*100) | J16: =J6 -> 0 | K16: =K6-J6 -> 0 | L16: =L6-K6 -> 0 | M16: =M6-L6 -> 0 | N16: =N6-M6 -> 0 | O16: =O6-N6 -> 0 | P16: =P6-O6 -> 0 | Q16: =Q6-P6 -> 0 | R16: =R6-Q6 -> 0 | ... X16: =X6-W6 -> 0 | AC16: 0 | AD16: =$AD$5 -> 0.25 | AE16: 0 | AF16: =+AD16+($D$15/100) -> 0.25 | AG16: 0 | AH16: =+AF16+($D$15/100) -> 0.25 | AI16: 0 | AJ16: =+AH16+($D$15/100) -> 0.25 | AK16: 0 | AL16: =+AJ16+($D$15/100) -> 0.25 | AM16: 0 | AN16: =+AL16+($D$15/100) -> 0.25
B17: Desvío uniformidad planteo | D17: =IF(SUM(F6:F13)=0,0,AVERAGE(F6:F13)) -> 0 | E17: cm | J17: =J7 -> 0 | K17: =K7-J7 -> 0 | L17: =L7-K7 -> 0 | M17: =M7-L7 -> 0 | N17: =N7-M7 -> 0 | O17: =O7-N7 -> 0 | P17: =P7-O7 -> 0 | Q17: =Q7-P7 -> 0 | R17: =R7-Q7 -> 0 | ... X17: =X7-W7 -> 0 | AC17: 0 | AD17: =$AD$5 -> 0.25 | AE17: 0 | AF17: =+AD17+($D$15/100) -> 0.25 | AG17: 0 | AH17: =+AF17+($D$15/100) -> 0.25 | AI17: 0 | AJ17: =+AH17+($D$15/100) -> 0.25 | AK17: 0 | AL17: =+AJ17+($D$15/100) -> 0.25 | AM17: 0 | AN17: =+AL17+($D$15/100) -> 0.25
B18: COEFICIENTE DE VARIACIÓN | D18: =IF(SUM(G6:G13)=0,0,AVERAGE(G6:G13)) -> 0 | J18: =J8 -> 0 | K18: =K8-J8 -> 0 | L18: =L8-K8 -> 0 | M18: =M8-L8 -> 0 | N18: =N8-M8 -> 0 | O18: =O8-N8 -> 0 | P18: =P8-O8 -> 0 | Q18: =Q8-P8 -> 0 | R18: =R8-Q8 -> 0 | ... X18: =X8-W8 -> 0
J19: =J9 -> 0 | K19: =K9-J9 -> 0 | L19: =L9-K9 -> 0 | M19: =M9-L9 -> 0 | N19: =N9-M9 -> 0 | O19: =O9-N9 -> 0 | P19: =P9-O9 -> 0 | Q19: =Q9-P9 -> 0 | R19: =R9-Q9 -> 0 | ... X19: =X9-W9 -> 0 | AC19: DISTANCIAMIENTO ENTRE PLANTAS IDEAL-DATOS ORIGEN GRAFICO
B20: Distribución espacial | J20: =J10 -> 0 | K20: =K10-J10 -> 0 | L20: =L10-K10 -> 0 | M20: =M10-L10 -> 0 | N20: =N10-M10 -> 0 | O20: =O10-N10 -> 0 | P20: =P10-O10 -> 0 | Q20: =Q10-P10 -> 0 | R20: =R10-Q10 -> 0 | ... X20: =X10-W10 -> 0 | AC20: =100/(AI23/(100*(100/($D$15/100)))) -> #DIV/0! | AD20: =+$AC$20*J5 -> #DIV/0! | AE20: =+$AC$20*K5 -> #DIV/0! | AF20: =+$AC$20*L5 -> #DIV/0! | AG20: =+$AC$20*M5 -> #DIV/0! | AH20: =+$AC$20*N5 -> #DIV/0! | AI20: =+$AC$20*O5 -> #DIV/0! | AJ20: =+$AC$20*P5 -> #DIV/0! | AK20: =+$AC$20*Q5 -> #DIV/0! | ... AQ20: =+$AC$20*W5 -> #DIV/0!
J21: =J11 -> 0 | K21: =K11-J11 -> 0 | L21: =L11-K11 -> 0 | M21: =M11-L11 -> 0 | N21: =N11-M11 -> 0 | O21: =O11-N11 -> 0 | P21: =P11-O11 -> 0 | Q21: =Q11-P11 -> 0 | R21: =R11-Q11 -> 0 | ... X21: =X11-W11 -> 0 | AC21: =+$AN$5+($D$15/100) -> 0.25 | AD21: =+$AN$5+($D$15/100) -> 0.25 | AE21: =+$AN$5+($D$15/100) -> 0.25 | AF21: =+$AN$5+($D$15/100) -> 0.25 | AG21: =+$AN$5+($D$15/100) -> 0.25 | AH21: =+$AN$5+($D$15/100) -> 0.25 | AI21: =+$AN$5+($D$15/100) -> 0.25 | AJ21: =+$AN$5+($D$15/100) -> 0.25 | ... AQ21: =+$AN$5+($D$15/100) -> 0.25
AC23: PL/HA-DATO ORIGEN GRAFICO= | AI23: =IF(B7="",D16,B7) -> 0
AC26: Densidad de siembra | AH26: =B7 -> 0
AC27: Distancia entre surcos | AH27: =D15/100 -> 0
AC28: Distancia eq 10 m2 (m) | AH28: =IF(AH27="","",10/AH27) -> #DIV/0!
J29: Observaciones: | AC29: Semillas/m lineal | AH29: =IF(AH27="","",1*(AH26/1000)/AH28) -> #DIV/0!
AC30: Distancia e/semillas(cm) | AH30: =IF(AH29="","",1/AH29*100) -> #DIV/0!
AC32: Doble (cm) | AH32: =IF(AH30="","",3) -> #DIV/0!
AC33: Fallo (cm) | AH33: =IF(AH27="","",2*AH30) -> #DIV/0!
AC34: Aceptable

Sheet L7
B1: RECUENTOS POR LOTE - MAIZ | AC1: Distanciamiento entre plantas- DATOS DE ORIGEN GRAFICO
B2: Establecimiento: | F2: Fecha: | K2: Estado Fenológico:
AC3: Sector 1 | AG3: Sector 2 | AK3: Sector 3
B4: Potrero: | D4: Dist.med. | E4: Plantas | F4: Desvío | G4: C.V. | H4: Distancias acumuladas entre plantas | AC4: S 1 | AE4: S 2 | AG4: S 1 | AI4: S 2 | AK4: S 1 | AM4: S 2
B5: Sitio: | D5: cm | E5: por ha | F5: plant.cm | J5: 2 | K5: 3 | L5: 4 | M5: 5 | N5: 6 | O5: 7 | P5: 8 | Q5: 9 | R5: 10 | S5: 11 | T5: 12 | U5: 13 | V5: 14 | W5: 15 | X5: 16 | AC5: {=TRANSPOSE(J6:X6)} -> 0 | AD5: 0.25 | AE5: {=TRANSPOSE(J7:X7)} -> 0 | AF5: =+AD5+($D$15/100) -> 0.25 | AG5: {=TRANSPOSE(J8:X8)} -> 0 | AH5: =+AF5+($D$15/100) -> 0.25 | AI5: {=TRANSPOSE(J9:X9)} -> 0 | AJ5: =+AH5+($D$15/100) -> 0.25 | AK5: {=TRANSPOSE(J10:X10)} -> 0 | AL5: =+AJ5+($D$15/100) -> 0.25 | AM5: {=TRANSPOSE(J11:X11)} -> 0 | AN5: =+AL5+($D$15/100) -> 0.25
B6: Densidad de Siembra: | D6: =IF(SUM(J16:X16)=0,0,AVERAGE(J16:X16)) -> 0 | E6: =IF(D6=0,"",100/D6/$D$15*100*10000) | F6: =IF(D6=0,"",STDEV(J16:X16)) | G6: =IF(F6="","",F6/D6) | H6: Sector 1 | I6: Surco 1 | AC6: 0 | AD6: =$AD$5 -> 0.25 | AE6: 0 | AF6: =+AD6+($D$15/100) -> 0.25 | AG6: 0 | AH6: =+AF6+($D$15/100) -> 0.25 | AI6: 0 | AJ6: =+AH6+($D$15/100) -> 0.25 | AK6: 0 | AL6: =+AJ6+($D$15/100) -> 0.25 | AM6: 0 | AN6: =+AL6+($D$15/100) -> 0.25
C7: sem/ha | D7: =IF(SUM(J17:X17)=0,0,AVERAGE(J17:X17)) -> 0 | E7: =IF(D7=0,"",100/D7/$D$15*100*10000) | F7: =IF(D7=0,"",STDEV(J17:X17)) | G7: =IF(F7="","",F7/D7) | I7: Surco 2 | AC7: 0 | AD7: =$AD$5 -> 0.25 | AE7: 0 | AF7: =+AD7+($D$15/100) -> 0.25 | AG7: 0 | AH7: =+AF7+($D$15/100) -> 0.25 | AI7: 0 | AJ7: =+AH7+($D$15/100) -> 0.25 | AK7: 0 | AL7: =+AJ7+($D$15/100) -> 0.25 | AM7: 0 | AN7: =+AL7+($D$15/100) -> 0.25
B8: Antecesor: | D8: =IF(SUM(J18:X18)=0,0,AVERAGE(J18:X18)) -> 0 | E8: =IF(D8=0,"",100/D8/$D$15*100*10000) | F8: =IF(D8=0,"",STDEV(J18:X18)) | G8: =IF(F8="","",F8/D8) | H8: Sector 2 | I8: Surco 1 | AC8: 0 | AD8: =$AD$5 -> 0.25 | AE8: 0 | AF8: =+AD8+($D$15/100) -> 0.25 | AG8: 0 | AH8: =+AF8+($D$15/100) -> 0.25 | AI8: 0 | AJ8: =+AH8+($D$15/100) -> 0.25 | AK8: 0 | AL8: =+AJ8+($D$15/100) -> 0.25 | AM8: 0 | AN8: =+AL8+($D$15/100) -> 0.25
D9: =IF(SUM(J19:X19)=0,0,AVERAGE(J19:X19)) -> 0 | E9: =IF(D9=0,"",100/D9/$D$15*100*10000) | F9: =IF(D9=0,"",STDEV(J19:X19)) | G9: =IF(F9="","",F9/D9) | I9: Surco 2 | AC9: 0 | AD9: =$AD$5 -> 0.25 | AE9: 0 | AF9: =+AD9+($D$15/100) -> 0.25 | AG9: 0 | AH9: =+AF9+($D$15/100) -> 0.25 | AI9: 0 | AJ9: =+AH9+($D$15/100) -> 0.25 | AK9: 0 | AL9: =+AJ9+($D$15/100) -> 0.25 | AM9: 0 | AN9: =+AL9+($D$15/100) -> 0.25
B10: Nombre Contratista: | D10: =IF(SUM(J20:X20)=0,0,AVERAGE(J20:X20)) -> 0 | E10: =IF(D10=0,"",100/D10/$D$15*100*10000) | F10: =IF(D10=0,"",STDEV(J20:X20)) | G10: =IF(F10="","",F10/D10) | H10: Sector 3 | I10: Surco 1 | AC10: 0 | AD10: =$AD$5 -> 0.25 | AE10: 0 | AF10: =+AD10+($D$15/100) -> 0.25 | AG10: 0 | AH10: =+AF10+($D$15/100) -> 0.25 | AI10: 0 | AJ10: =+AH10+($D$15/100) -> 0.25 | AK10: 0 | AL10: =+AJ10+($D$15/100) -> 0.25 | AM10: 0 | AN10: =+AL10+($D$15/100) -> 0.25
D11: =IF(SUM(J21:X21)=0,0,AVERAGE(J21:X21)) -> 0 | E11: =IF(D11=0,"",100/D11/$D$15*100*10000) | F11: =IF(D11=0,"",STDEV(J21:X21)) | G11: =IF(F11="","",F11/D11) | I11: Surco 2 | AC11: 0 | AD11: =$AD$5 -> 0.25 | AE11: 0 | AF11: =+AD11+($D$15/100) -> 0.25 | AG11: 0 | AH11: =+AF11+($D$15/100) -> 0.25 | AI11: 0 | AJ11: =+AH11+($D$15/100) -> 0.25 | AK11: 0 | AL11: =+AJ11+($D$15/100) -> 0.25 | AM11: 0 | AN11: =+AL11+($D$15/100) -> 0.25
B12: Sembradora: | AC12: 0 | AD12: =$AD$5 -> 0.25 | AE12: 0 | AF12: =+AD12+($D$15/100) -> 0.25 | AG12: 0 | AH12: =+AF12+($D$15/100) -> 0.25 | AI12: 0 | AJ12: =+AH12+($D$15/100) -> 0.25 | AK12: 0 | AL12: =+AJ12+($D$15/100) -> 0.25 | AM12: 0 | AN12: =+AL12+($D$15/100) -> 0.25
AC13: 0 | AD13: =$AD$5 -> 0.25 | AE13: 0 | AF13: =+AD13+($D$15/100) -> 0.25 | AG13: 0 | AH13: =+AF13+($D$15/100) -> 0.25 | AI13: 0 | AJ13: =+AH13+($D$15/100) -> 0.25 | AK13: 0 | AL13: =+AJ13+($D$15/100) -> 0.25 | AM13: 0 | AN13: =+AL13+($D$15/100) -> 0.25
D14: =IF(COUNTIF(D6:D13,">0"),SUM(D6:D13)/COUNTIF(D6:D13,">0"),"") | J14: Distancia entre plantas | AC14: 0 | AD14: =$AD$5 -> 0.25 | AE14: 0 | AF14: =+AD14+($D$15/100) -> 0.25 | AG14: 0 | AH14: =+AF14+($D$15/100) -> 0.25 | AI14: 0 | AJ14: =+AH14+($D$15/100) -> 0.25 | AK14: 0 | AL14: =+AJ14+($D$15/100) -> 0.25 | AM14: 0 | AN14: =+AL14+($D$15/100) -> 0.25
